Workbook

Sheet 構想
C2: 工程表構想
C5: 2000番台
C6: 工程項目 | D6: 表記単位 | E6: 項目 | F6: リンク先 | G6: 担当部署 | H6: 期間 | I6: 目的（知りたい情報）＆要望
C7: 受注 | D7: 工番 | E7: 受注説明会 | G7: 営業部 | H7: ○○月○○日～○○月○○日 | I7: 実施の未or済 受注後の早い時期（2週間以内）
C8: 基本設計＆計画承認 | D8: 機械 | E8: 計画設計 | F8: 設計工程 | G8: 設計部
E9: 計画図客先提出 | G9: 営業部
E10: 客先承認 | G10: 営業部
D11: 盤＆制御（電気関係） | E11: 操作盤外形図検討 | F11: 電気工程会議議事録 | G11: 操業部
E12: 外形図客先提出 | G12: 営業部
E13: 電気図面設計 | G13: 電気技術課
E14: 電気図面客先提出 | G14: 営業部
E15: 客先承認 | G15: 営業部
C16: 部品手配➀ | D16: 機械 | E16: 長納期購入品検討＆手配 | F16: Production Control | G16: 設計部、電技課、資材課 | I16: 長納期品の対象と手配状況の把握と納期の把握
D17: 盤 | E17: 電気品 筐体手配 | F17: Production Control | G17: 電気技術課、資材課
D18: 機械 | E18: 長納期製作品手配＆手配 | F18: Production Control | G18: 設計部、製管課 | I18: 長納期品の対象と手配状況の把握と納期の把握
C19: 出図＆部品手配➁ | D19: ユニット単位 | E19: 出図進捗 | F19: 設計工程 | G19: 設計部 | I19: 進捗と全体量、残り図面量の把握
E20: 製作品納期 | F20: Production Control | G20: 製管課 | I20: 部品が組立時にそろうかの把握
E21: 組立図進捗 | F21: 設計工程 | G21: 設計部 | I21: 部品が組立時にそろうかの把握
E22: 神戸納入予定日 | F22: Production Control | G22: 明石工場 | I22: 製作品納期とは別に検査後の神戸への納入日を把握する
E23: 艤装出図進捗 | F23: 設計工程 | G23: 設計部 | I23: 進捗と組立工程への影響回避のため
E24: 製作品納期 | F24: Production Control | G24: 製管課 | I24: 部品が組立時にそろうかの把握
E25: 艤装組立図進捗 | F25: 設計工程 | G25: 設計部 | I25: 部品が組立時にそろうかの把握
E26: 神戸納入予定日 | F26: Production Control | G26: 明石工場 | I26: 製作品納期とは別に検査後の神戸への納入日を把握する
C27: 電気設計 | D27: 盤 | E27: 最終電気図面 | F27: 電気工程会議議事録 | G27: 電気技術課
C28: 盤組立 | D28: 盤 | E28: 盤組立 | F28: 組立工程表 | G28: 電装課
C29: 組立 | D29: 全体工程 | E29: 組立期間 | F29: 組立工程表 | G29: 組立部
D30: サブ組立（ユニット単位） | E30: 塗装 | G30: 組立課 | I30: 塗装場の状況把握 状況次第で神戸送りを早める場合がある
E31: 組立 | F31: 組立工程表 | G31: 組立課 | I31: 組立進捗把握と部品手配納期の調整ができる
D32: 機械単位 | E32: 据付 | F32: 組立工程表 | G32: 組立課 | I32: 全体の進捗と工程として間に合うか確認
E33: 組立 | F33: 組立工程表 | G33: 組立課
E34: 艤装 | F34: 組立工程表 | G34: 組立部
E35: 電気艤装 | F35: 組立工程表 | G35: 電装課
C36: 組立完成 | D36: 機械単位 | E36: 外観検査 | F36: 工程会議議事録 | G36: 品証課 | I36: 検査結果を関係者で共有する。（Teamsにあげる）
D37: 盤単位 | E37: タスクリスト作成 | F37: タスクリスト | G37: 製管課 | I37: 外観検査での指摘事項から記載する
C38: 試運転 | D38: 盤単位 | E38: IOチェック | F38: 操業工程表 | G38: 操業部 | I38: 全体の進捗と工程として間に合うか確認
E39: 単体動作確認 | F39: 操業工程表 | G39: 操業部
E40: 全体動作確認 | F40: 操業工程表 | G40: 操業部
E41: プログラム調整 | F41: 操業工程表 | G41: 操業部
E42: 機械調整 | F42: 操業工程表 | G42: 操業部
E43: サイクルタイム確認 | F43: 操業工程表 | G43: 操業部
...

Sheet 具体例
B2: 工事番号 | C2: 機械 | D2: ユニット | E2: タスク | F2: リンク先 | G2: 担当者 | H2: 達成率 | I2: 開始日 | J2: 終了日 | K2: 2024年 | BT2: 2025年 | PU2: 2026年
K3: 11月 | AO3: 12月 | BT3: 1月 | CY3: 2月 | EA3: 3月 | FF3: 4月 | GJ3: 5月 | HO3: 6月 | IS3: 7月 | JX3: 8月 | LC3: 9月 | MG3: 10月 | NL3: 11月 | OP3: 12月 | PU3: 1月 | QZ3: 2月
K4: =+_xlfn.XLOOKUP("月",K$7,K$6,0) -> 0 | L4: =+_xlfn.XLOOKUP("月",L$7,L$6,0) -> 0 | M4: =+_xlfn.XLOOKUP("月",M$7,M$6,0) -> 0 | N4: =+_xlfn.XLOOKUP("月",N$7,N$6,0) -> 4 | O4: =+_xlfn.XLOOKUP("月",O$7,O$6,0) -> 0 | P4: =+_xlfn.XLOOKUP("月",P$7,P$6,0) -> 0 | Q4: =+_xlfn.XLOOKUP("月",Q$7,Q$6,0) -> 0 | R4: =+_xlfn.XLOOKUP("月",R$7,R$6,0) -> 0 | ... SA4: =+_xlfn.XLOOKUP("月",SA$7,SA$6,0) -> 0
K5: 45597 | L5: 45598 | M5: 45599 | N5: 45600 | O5: 45601 | P5: 45602 | Q5: 45603 | R5: 45604 | S5: 45605 | T5: 45606 | U5: 45607 | V5: 45608 | W5: 45609 | X5: 45610 | Y5: 45611 | Z5: 45612 | AA5: 45613 | AB5: 45614 | AC5: 45615 | AD5: 45616 | AE5: 45617 | AF5: 45618 | AG5: 45619 | AH5: 45620 | AI5: 45621 | AJ5: 45622 | AK5: 45623 | AL5: 45624 | AM5: 45625 | AN5: 45626 | AO5: 45627 | AP5: 45628 | AQ5: 45629 | AR5: 45630 | AS5: 45631 | AT5: 45632 | AU5: 45633 | AV5: 45634 | AW5: 45635 | AX5: 45636 | AY5: 45637 | AZ5: 45638 | BA5: 45639 | BB5: 45640 | BC5: 45641 | BD5: 45642 | BE5: 45643 | BF5: 45644 | BG5: 45645 | BH5: 45646 | BI5: 45647 | BJ5: 45648 | BK5: 45649 | BL5: 45650 | BM5: 45651 | BN5: 45652 | BO5: 45653 | BP5: 45654 | BQ5: 45655 | BR5: 45656 | BS5: 45657 | BT5: 45658 | BU5: 45659 | BV5: 45660 | BW5: 45661 | BX5: 45662 | BY5: 45663 | BZ5: 45664 | CA5: 45665 | CB5: 45666 | CC5: 45667 | CD5: 45668 | CE5: 45669 | CF5: 45670 | CG5: 45671 | CH5: 45672 | CI5: 45673 | CJ5: 45674 | CK5: 45675 | CL5: 45676 | CM5: 45677 | CN5: 45678 | CO5: 45679 | CP5: 45680 | CQ5: 45681 | CR5: 45682 | CS5: 45683 | CT5: 45684 | CU5: 45685 | CV5: 45686 | CW5: 45687 | CX5: 45688 | CY5: 45689 | CZ5: 45690 | DA5: 45691 | DB5: 45692 | DC5: 45693 | DD5: 45694 | DE5: 45695 | DF5: 45696 | DG5: 45697 | DH5: 45698 | DI5: 45699 | DJ5: 45700 | DK5: 45701 | DL5: 45702 | DM5: 45703 | DN5: 45704 | DO5: 45705 | DP5: 45706 | DQ5: 45707 | DR5: 45708 | DS5: 45709 | DT5: 45710 | DU5: 45711 | DV5: 45712 | DW5: 45713 | DX5: 45714 | DY5: 45715 | DZ5: 45716 | EA5: 45717 | EB5: 45718 | EC5: 45719 | ED5: 45720 | EE5: 45721 | EF5: 45722 | EG5: 45723 | EH5: 45724 | EI5: 45725 | EJ5: 45726 | EK5: 45727 | EL5: 45728 | EM5: 45729 | EN5: 45730 | EO5: 45731 | EP5: 45732 | EQ5: 45733 | ER5: 45734 | ES5: 45735 | ET5: 45736 | EU5: 45737 | EV5: 45738 | EW5: 45739 | EX5: 45740 | EY5: 45741 | EZ5: 45742 | FA5: 45743 | FB5: 45744 | FC5: 45745 | FD5: 45746 | FE5: 45747 | FF5: 45748 | FG5: 45749 | FH5: 45750 | FI5: 45751 | FJ5: 45752 | FK5: 45753 | FL5: 45754 | FM5: 45755 | FN5: 45756 | FO5: 45757 | FP5: 45758 | FQ5: 45759 | FR5: 45760 | FS5: 45761 | FT5: 45762 | FU5: 45763 | FV5: 45764 | FW5: 45765 | FX5: 45766 | FY5: 45767 | FZ5: 45768 | GA5: 45769 | GB5: 45770 | GC5: 45771 | GD5: 45772 | GE5: 45773 | GF5: 45774 | GG5: 45775 | GH5: 45776 | GI5: 45777 | GJ5: 45778 | GK5: 45779 | GL5: 45780 | GM5: 45781 | GN5: 45782 | GO5: 45783 | GP5: 45784 | GQ5: 45785 | GR5: 45786 | GS5: 45787 | GT5: 45788 | GU5: 45789 | GV5: 45790 | GW5: 45791 | GX5: 45792 | GY5: 45793 | GZ5: 45794 | HA5: 45795 | HB5: 45796 | HC5: 45797 | HD5: 45798 | HE5: 45799 | HF5: 45800 | HG5: 45801 | HH5: 45802 | HI5: 45803 | HJ5: 45804 | HK5: 45805 | HL5: 45806 | HM5: 45807 | HN5: 45808 | HO5: 45809 | HP5: 45810 | HQ5: 45811 | HR5: 45812 | HS5: 45813 | HT5: 45814 | HU5: 45815 | HV5: 45816 | HW5: 45817 | HX5: 45818 | HY5: 45819 | HZ5: 45820 | IA5: 45821 | IB5: 45822 | IC5: 45823 | ID5: 45824 | IE5: 45825 | IF5: 45826 | IG5: 45827 | IH5: 45828 | II5: 45829 | IJ5: 45830 | IK5: 45831 | IL5: 45832 | IM5: 45833 | IN5: 45834 | IO5: 45835 | IP5: 45836 | IQ5: 45837 | IR5: 45838 | IS5: 45839 | IT5: 45840 | IU5: 45841 | IV5: 45842 | IW5: 45843 | IX5: 45844 | IY5: 45845 | IZ5: 45846 | JA5: 45847 | JB5: 45848 | JC5: 45849 | JD5: 45850 | JE5: 45851 | JF5: 45852 | JG5: 45853 | JH5: 45854 | JI5: 45855 | JJ5: 45856 | JK5: 45857 | JL5: 45858 | JM5: 45859 | JN5: 45860 | JO5: 45861 | JP5: 45862 | JQ5: 45863 | JR5: 45864 | JS5: 45865 | JT5: 45866 | JU5: 45867 | JV5: 45868 | JW5: 45869 | JX5: 45870 | JY5: 45871 | JZ5: 45872 | KA5: 45873 | KB5: 45874 | KC5: 45875 | KD5: 45876 | KE5: 45877 | KF5: 45878 | KG5: 45879 | KH5: 45880 | KI5: 45881 | KJ5: 45882 | KK5: 45883 | KL5: 45884 | KM5: 45885 | KN5: 45886 | KO5: 45887 | KP5: 45888 | KQ5: 45889 | KR5: 45890 | KS5: 45891 | KT5: 45892 | KU5: 45893 | KV5: 45894 | KW5: 45895 | KX5: 45896 | KY5: 45897 | KZ5: 45898 | LA5: 45899 | LB5: 45900 | LC5: 45901 | LD5: 45902 | LE5: 45903 | LF5: 45904 | LG5: 45905 | LH5: 45906 | LI5: 45907 | LJ5: 45908 | LK5: 45909 | LL5: 45910 | LM5: 45911 | LN5: 45912 | LO5: 45913 | LP5: 45914 | LQ5: 45915 | LR5: 45916 | LS5: 45917 | LT5: 45918 | LU5: 45919 | LV5: 45920 | LW5: 45921 | LX5: 45922 | LY5: 45923 | LZ5: 45924 | MA5: 45925 | MB5: 45926 | MC5: 45927 | MD5: 45928 | ME5: 45929 | MF5: 45930 | MG5: 45931 | MH5: 45932 | MI5: 45933 | MJ5: 45934 | MK5: 45935 | ML5: 45936 | MM5: 45937 | MN5: 45938 | MO5: 45939 | MP5: 45940 | MQ5: 45941 | MR5: 45942 | MS5: 45943 | MT5: 45944 | MU5: 45945 | MV5: 45946 | MW5: 45947 | MX5: 45948 | MY5: 45949 | MZ5: 45950 | NA5: 45951 | NB5: 45952 | NC5: 45953 | ND5: 45954 | NE5: 45955 | NF5: 45956 | NG5: 45957 | NH5: 45958 | NI5: 45959 | NJ5: 45960 | NK5: 45961 | NL5: 45962 | NM5: 45963 | NN5: 45964 | NO5: 45965 | NP5: 45966 | NQ5: 45967 | NR5: 45968 | NS5: 45969 | NT5: 45970 | NU5: 45971 | NV5: 45972 | NW5: 45973 | NX5: 45974 | NY5: 45975 | NZ5: 45976 | OA5: 45977 | OB5: 45978 | OC5: 45979 | OD5: 45980 | OE5: 45981 | OF5: 45982 | OG5: 45983 | OH5: 45984 | OI5: 45985 | OJ5: 45986 | OK5: 45987 | OL5: 45988 | OM5: 45989 | ON5: 45990 | OO5: 45991 | OP5: 45992 | OQ5: 45993 | OR5: 45994 | OS5: 45995 | OT5: 45996 | OU5: 45997 | OV5: 45998 | OW5: 45999 | OX5: 46000 | OY5: 46001 | OZ5: 46002 | PA5: 46003 | PB5: 46004 | PC5: 46005 | PD5: 46006 | PE5: 46007 | PF5: 46008 | PG5: 46009 | PH5: 46010 | PI5: 46011 | PJ5: 46012 | PK5: 46013 | PL5: 46014 | PM5: 46015 | PN5: 46016 | PO5: 46017 | PP5: 46018 | PQ5: 46019 | PR5: 46020 | PS5: 46021 | PT5: 46022 | PU5: 46023 | PV5: 46024 | PW5: 46025 | PX5: 46026 | PY5: 46027 | PZ5: 46028 | QA5: 46029 | QB5: 46030 | QC5: 46031 | QD5: 46032 | QE5: 46033 | QF5: 46034 | QG5: 46035 | QH5: 46036 | QI5: 46037 | QJ5: 46038 | QK5: 46039 | QL5: 46040 | QM5: 46041 | QN5: 46042 | QO5: 46043 | QP5: 46044 | QQ5: 46045 | QR5: 46046 | QS5: 46047 | QT5: 46048 | QU5: 46049 | QV5: 46050 | QW5: 46051 | QX5: 46052 | QY5: 46053 | QZ5: 46054 | RA5: 46055 | RB5: 46056 | RC5: 46057 | RD5: 46058 | RE5: 46059 | RF5: 46060 | RG5: 46061 | RH5: 46062 | RI5: 46063 | RJ5: 46064 | RK5: 46065 | RL5: 46066 | RM5: 46067 | RN5: 46068 | RO5: 46069 | RP5: 46070 | RQ5: 46071 | RR5: 46072 | RS5: 46073 | RT5: 46074 | RU5: 46075 | RV5: 46076 | RW5: 46077 | RX5: 46078 | RY5: 46079 | RZ5: 46080 | SA5: 46081
K6: 1 | L6: =+K6+1 -> 2 | M6: =+L6+1 -> 3 | N6: =+M6+1 -> 4 | O6: =+N6+1 -> 5 | P6: =+O6+1 -> 6 | Q6: =+P6+1 -> 7 | R6: =+Q6+1 -> 8 | S6: =+R6+1 -> 9 | ... AN6: =+AM6+1 -> 30 | AO6: 1 | AP6: =+AO6+1 -> 2 | AQ6: =+AP6+1 -> 3 | AR6: =+AQ6+1 -> 4 | AS6: =+AR6+1 -> 5 | AT6: =+AS6+1 -> 6 | AU6: =+AT6+1 -> 7 | AV6: =+AU6+1 -> 8 | AW6: =+AV6+1 -> 9 | ... BS6: =+BR6+1 -> 31 | BT6: 1 | BU6: =+BT6+1 -> 2 | BV6: =+BU6+1 -> 3 | BW6: =+BV6+1 -> 4 | BX6: =+BW6+1 -> 5 | BY6: =+BX6+1 -> 6 | BZ6: =+BY6+1 -> 7 | CA6: =+BZ6+1 -> 8 | CB6: =+CA6+1 -> 9 | ... CX6: =+CW6+1 -> 31 | CY6: 1 | CZ6: =+CY6+1 -> 2 | DA6: =+CZ6+1 -> 3 | DB6: =+DA6+1 -> 4 | DC6: =+DB6+1 -> 5 | DD6: =+DC6+1 -> 6 | DE6: =+DD6+1 -> 7 | DF6: =+DE6+1 -> 8 | DG6: =+DF6+1 -> 9 | ... DZ6: =+DY6+1 -> 28 | EA6: 1 | EB6: =+EA6+1 -> 2 | EC6: =+EB6+1 -> 3 | ED6: =+EC6+1 -> 4 | EE6: =+ED6+1 -> 5 | EF6: =+EE6+1 -> 6 | EG6: =+EF6+1 -> 7 | EH6: =+EG6+1 -> 8 | EI6: =+EH6+1 -> 9 | ... FE6: =+FD6+1 -> 31 | FF6: 1 | FG6: =+FF6+1 -> 2 | FH6: =+FG6+1 -> 3 | FI6: =+FH6+1 -> 4 | FJ6: =+FI6+1 -> 5 | FK6: =+FJ6+1 -> 6 | FL6: =+FK6+1 -> 7 | FM6: =+FL6+1 -> 8 | FN6: =+FM6+1 -> 9 | ... GI6: =+GH6+1 -> 30 | GJ6: 1 | GK6: =+GJ6+1 -> 2 | GL6: =+GK6+1 -> 3 | GM6: =+GL6+1 -> 4 | GN6: =+GM6+1 -> 5 | GO6: =+GN6+1 -> 6 | GP6: =+GO6+1 -> 7 | GQ6: =+GP6+1 -> 8 | GR6: =+GQ6+1 -> 9 | ... HN6: =+HM6+1 -> 31 | HO6: 1 | HP6: =+HO6+1 -> 2 | HQ6: =+HP6+1 -> 3 | HR6: =+HQ6+1 -> 4 | HS6: =+HR6+1 -> 5 | HT6: =+HS6+1 -> 6 | HU6: =+HT6+1 -> 7 | HV6: =+HU6+1 -> 8 | HW6: =+HV6+1 -> 9 | ... IR6: =+IQ6+1 -> 30 | IS6: 1 | IT6: =+IS6+1 -> 2 | IU6: =+IT6+1 -> 3 | IV6: =+IU6+1 -> 4 | IW6: =+IV6+1 -> 5 | IX6: =+IW6+1 -> 6 | IY6: =+IX6+1 -> 7 | IZ6: =+IY6+1 -> 8 | JA6: =+IZ6+1 -> 9 | ... JW6: =+JV6+1 -> 31 | JX6: 1 | JY6: =+JX6+1 -> 2 | JZ6: =+JY6+1 -> 3 | KA6: =+JZ6+1 -> 4 | KB6: =+KA6+1 -> 5 | KC6: =+KB6+1 -> 6 | KD6: =+KC6+1 -> 7 | KE6: =+KD6+1 -> 8 | KF6: =+KE6+1 -> 9 | ... LB6: =+LA6+1 -> 31 | LC6: 1 | LD6: =+LC6+1 -> 2 | LE6: =+LD6+1 -> 3 | LF6: =+LE6+1 -> 4 | LG6: =+LF6+1 -> 5 | LH6: =+LG6+1 -> 6 | LI6: =+LH6+1 -> 7 | LJ6: =+LI6+1 -> 8 | LK6: =+LJ6+1 -> 9 | ... MF6: =+ME6+1 -> 30 | MG6: 1 | MH6: =+MG6+1 -> 2 | MI6: =+MH6+1 -> 3 | MJ6: =+MI6+1 -> 4 | MK6: =+MJ6+1 -> 5 | ML6: =+MK6+1 -> 6 | MM6: =+ML6+1 -> 7 | MN6: =+MM6+1 -> 8 | MO6: =+MN6+1 -> 9 | ... NK6: =+NJ6+1 -> 31 | NL6: 1 | NM6: =+NL6+1 -> 2 | NN6: =+NM6+1 -> 3 | NO6: =+NN6+1 -> 4 | NP6: =+NO6+1 -> 5 | NQ6: =+NP6+1 -> 6 | NR6: =+NQ6+1 -> 7 | NS6: =+NR6+1 -> 8 | NT6: =+NS6+1 -> 9 | ... OO6: =+ON6+1 -> 30 | OP6: 1 | OQ6: =+OP6+1 -> 2 | OR6: =+OQ6+1 -> 3 | OS6: =+OR6+1 -> 4 | OT6: =+OS6+1 -> 5 | OU6: =+OT6+1 -> 6 | OV6: =+OU6+1 -> 7 | OW6: =+OV6+1 -> 8 | OX6: =+OW6+1 -> 9 | ... PT6: =+PS6+1 -> 31 | PU6: 1 | PV6: =+PU6+1 -> 2 | PW6: =+PV6+1 -> 3 | PX6: =+PW6+1 -> 4 | PY6: =+PX6+1 -> 5 | PZ6: =+PY6+1 -> 6 | QA6: =+PZ6+1 -> 7 | QB6: =+QA6+1 -> 8 | QC6: =+QB6+1 -> 9 | ... QY6: =+QX6+1 -> 31 | QZ6: 1 | RA6: =+QZ6+1 -> 2 | RB6: =+RA6+1 -> 3 | RC6: =+RB6+1 -> 4 | RD6: =+RC6+1 -> 5 | RE6: =+RD6+1 -> 6 | RF6: =+RE6+1 -> 7 | RG6: =+RF6+1 -> 8 | RH6: =+RG6+1 -> 9 | ... SA6: =+RZ6+1 -> 28
K7: 金 | L7: 土 | M7: 日 | N7: 月 | O7: 火 | P7: 水 | Q7: 木 | R7: 金 | S7: 土 | T7: 日 | U7: 月 | V7: 火 | W7: 水 | X7: 木 | Y7: 金 | Z7: 土 | AA7: 日 | AB7: 月 | AC7: 火 | AD7: 水 | AE7: 木 | AF7: 金 | AG7: 土 | AH7: 日 | AI7: 月 | AJ7: 火 | AK7: 水 | AL7: 木 | AM7: 金 | AN7: 土 | AO7: 日 | AP7: 月 | AQ7: 火 | AR7: 水 | AS7: 木 | AT7: 金 | AU7: 土 | AV7: 日 | AW7: 月 | AX7: 火 | AY7: 水 | AZ7: 木 | BA7: 金 | BB7: 土 | BC7: 日 | BD7: 月 | BE7: 火 | BF7: 水 | BG7: 木 | BH7: 金 | BI7: 土 | BJ7: 日 | BK7: 月 | BL7: 火 | BM7: 水 | BN7: 木 | BO7: 金 | BP7: 土 | BQ7: 日 | BR7: 月 | BS7: 火 | BT7: 水 | BU7: 木 | BV7: 金 | BW7: 土 | BX7: 日 | BY7: 月 | BZ7: 火 | CA7: 水 | CB7: 木 | CC7: 金 | CD7: 土 | CE7: 日 | CF7: 月 | CG7: 火 | CH7: 水 | CI7: 木 | CJ7: 金 | CK7: 土 | CL7: 日 | CM7: 月 | CN7: 火 | CO7: 水 | CP7: 木 | CQ7: 金 | CR7: 土 | CS7: 日 | CT7: 月 | CU7: 火 | CV7: 水 | CW7: 木 | CX7: 金 | CY7: 土 | CZ7: 日 | DA7: 月 | DB7: 火 | DC7: 水 | DD7: 木 | DE7: 金 | DF7: 土 | DG7: 日 | DH7: 月 | DI7: 火 | DJ7: 水 | DK7: 木 | DL7: 金 | DM7: 土 | DN7: 日 | DO7: 月 | DP7: 火 | DQ7: 水 | DR7: 木 | DS7: 金 | DT7: 土 | DU7: 日 | DV7: 月 | DW7: 火 | DX7: 水 | DY7: 木 | DZ7: 金 | EA7: 土 | EB7: 日 | EC7: 月 | ED7: 火 | EE7: 水 | EF7: 木 | EG7: 金 | EH7: 土 | EI7: 日 | EJ7: 月 | EK7: 火 | EL7: 水 | EM7: 木 | EN7: 金 | EO7: 土 | EP7: 日 | EQ7: 月 | ER7: 火 | ES7: 水 | ET7: 木 | EU7: 金 | EV7: 土 | EW7: 日 | EX7: 月 | EY7: 火 | EZ7: 水 | FA7: 木 | FB7: 金 | FC7: 土 | FD7: 日 | FE7: 月 | FF7: 火 | FG7: 水 | FH7: 木 | FI7: 金 | FJ7: 土 | FK7: 日 | FL7: 月 | FM7: 火 | FN7: 水 | FO7: 木 | FP7: 金 | FQ7: 土 | FR7: 日 | FS7: 月 | FT7: 火 | FU7: 水 | FV7: 木 | FW7: 金 | FX7: 土 | FY7: 日 | FZ7: 月 | GA7: 火 | GB7: 水 | GC7: 木 | GD7: 金 | GE7: 土 | GF7: 日 | GG7: 月 | GH7: 火 | GI7: 水 | GJ7: 木 | GK7: 金 | GL7: 土 | GM7: 日 | GN7: 月 | GO7: 火 | GP7: 水 | GQ7: 木 | GR7: 金 | GS7: 土 | GT7: 日 | GU7: 月 | GV7: 火 | GW7: 水 | GX7: 木 | GY7: 金 | GZ7: 土 | HA7: 日 | HB7: 月 | HC7: 火 | HD7: 水 | HE7: 木 | HF7: 金 | HG7: 土 | HH7: 日 | HI7: 月 | HJ7: 火 | HK7: 水 | HL7: 木 | HM7: 金 | HN7: 土 | HO7: 日 | HP7: 月 | HQ7: 火 | HR7: 水 | HS7: 木 | HT7: 金 | HU7: 土 | HV7: 日 | HW7: 月 | HX7: 火 | HY7: 水 | HZ7: 木 | IA7: 金 | IB7: 土 | IC7: 日 | ID7: 月 | IE7: 火 | IF7: 水 | IG7: 木 | IH7: 金 | II7: 土 | IJ7: 日 | IK7: 月 | IL7: 火 | IM7: 水 | IN7: 木 | IO7: 金 | IP7: 土 | IQ7: 日 | IR7: 月 | IS7: 火 | IT7: 水 | IU7: 木 | IV7: 金 | IW7: 土 | IX7: 日 | IY7: 月 | IZ7: 火 | JA7: 水 | JB7: 木 | JC7: 金 | JD7: 土 | JE7: 日 | JF7: 月 | JG7: 火 | JH7: 水 | JI7: 木 | JJ7: 金 | JK7: 土 | JL7: 日 | JM7: 月 | JN7: 火 | JO7: 水 | JP7: 木 | JQ7: 金 | JR7: 土 | JS7: 日 | JT7: 月 | JU7: 火 | JV7: 水 | JW7: 木 | JX7: 金 | JY7: 土 | JZ7: 日 | KA7: 月 | KB7: 火 | KC7: 水 | KD7: 木 | KE7: 金 | KF7: 土 | KG7: 日 | KH7: 月 | KI7: 火 | KJ7: 水 | KK7: 木 | KL7: 金 | KM7: 土 | KN7: 日 | KO7: 月 | KP7: 火 | KQ7: 水 | KR7: 木 | KS7: 金 | KT7: 土 | KU7: 日 | KV7: 月 | KW7: 火 | KX7: 水 | KY7: 木 | KZ7: 金 | LA7: 土 | LB7: 日 | LC7: 月 | LD7: 火 | LE7: 水 | LF7: 木 | LG7: 金 | LH7: 土 | LI7: 日 | LJ7: 月 | LK7: 火 | LL7: 水 | LM7: 木 | LN7: 金 | LO7: 土 | LP7: 日 | LQ7: 月 | LR7: 火 | LS7: 水 | LT7: 木 | LU7: 金 | LV7: 土 | LW7: 日 | LX7: 月 | LY7: 火 | LZ7: 水 | MA7: 木 | MB7: 金 | MC7: 土 | MD7: 日 | ME7: 月 | MF7: 火 | MG7: 水 | MH7: 木 | MI7: 金 | MJ7: 土 | MK7: 日 | ML7: 月 | MM7: 火 | MN7: 水 | MO7: 木 | MP7: 金 | MQ7: 土 | MR7: 日 | MS7: 月 | MT7: 火 | MU7: 水 | MV7: 木 | MW7: 金 | MX7: 土 | MY7: 日 | MZ7: 月 | NA7: 火 | NB7: 水 | NC7: 木 | ND7: 金 | NE7: 土 | NF7: 日 | NG7: 月 | NH7: 火 | NI7: 水 | NJ7: 木 | NK7: 金 | NL7: 土 | NM7: 日 | NN7: 月 | NO7: 火 | NP7: 水 | NQ7: 木 | NR7: 金 | NS7: 土 | NT7: 日 | NU7: 月 | NV7: 火 | NW7: 水 | NX7: 木 | NY7: 金 | NZ7: 土 | OA7: 日 | OB7: 月 | OC7: 火 | OD7: 水 | OE7: 木 | OF7: 金 | OG7: 土 | OH7: 日 | OI7: 月 | OJ7: 火 | OK7: 水 | OL7: 木 | OM7: 金 | ON7: 土 | OO7: 日 | OP7: 月 | OQ7: 火 | OR7: 水 | OS7: 木 | OT7: 金 | OU7: 土 | OV7: 日 | OW7: 月 | OX7: 火 | OY7: 水 | OZ7: 木 | PA7: 金 | PB7: 土 | PC7: 日 | PD7: 月 | PE7: 火 | PF7: 水 | PG7: 木 | PH7: 金 | PI7: 土 | PJ7: 日 | PK7: 月 | PL7: 火 | PM7: 水 | PN7: 木 | PO7: 金 | PP7: 土 | PQ7: 日 | PR7: 月 | PS7: 火 | PT7: 水 | PU7: 木 | PV7: 金 | PW7: 土 | PX7: 日 | PY7: 月 | PZ7: 火 | QA7: 水 | QB7: 木 | QC7: 金 | QD7: 土 | QE7: 日 | QF7: 月 | QG7: 火 | QH7: 水 | QI7: 木 | QJ7: 金 | QK7: 土 | QL7: 日 | QM7: 月 | QN7: 火 | QO7: 水 | QP7: 木 | QQ7: 金 | QR7: 土 | QS7: 日 | QT7: 月 | QU7: 火 | QV7: 水 | QW7: 木 | QX7: 金 | QY7: 土 | QZ7: 日 | RA7: 月 | RB7: 火 | RC7: 水 | RD7: 木 | RE7: 金 | RF7: 土 | RG7: 日 | RH7: 月 | RI7: 火 | RJ7: 水 | RK7: 木 | RL7: 金 | RM7: 土 | RN7: 日 | RO7: 月 | RP7: 火 | RQ7: 水 | RR7: 木 | RS7: 金 | RT7: 土 | RU7: 日 | RV7: 月 | RW7: 火 | RX7: 水 | RY7: 木 | RZ7: 金 | SA7: 土
B8: 2809 | C8: ー | D8: ー | E8: 受注説明会 | F8: 社内製作仕様書 | G8: 岡本 | H8: 1 | I8: 45597 | J8: 45597
E9: 設計・出図 | F9: 出図状況
E10: 計画設計 | G10: 宮崎 | H10: 1 | I10: 45622 | J10: 45622
E11: 計画図客先提出 | G11: 岡本 | H11: 1 | I11: 45623 | J11: 45632
E12: 客先承認 | G12: ー | H12: 1 | I12: 45635 | J12: 45646
E13: 操作盤外形図検討 | F13: 電気工程会議議事録 | G13: 電気技術 | H13: 1 | I13: 45649 | J13: 45653
E14: 外形図客先提出 | G14: 電気技術 | H14: 1 | I14: 45663 | J14: 45667
E15: 電気図面設計 | G15: 電気技術 | H15: 1 | I15: 45670 | J15: 45674
E16: 電気図面客先提出 | G16: 電気技術 | H16: 1 | I16: 45677 | J16: 45681
E17: 客先承認 | G17: ー | H17: 1 | I17: 45684 | J17: 45688
E18: 長納期購入品検討＆手配 | F18: 長納期品手配状況 | G18: 製造管理 | H18: 1 | I18: 45689 | J18: 45695
E19: 電気品 筐体手配 | G19: 電気技術 | H19: 1 | I19: 45698 | J19: 45702
E20: 長納期製作品手配＆手配 | G20: 製造管理 | H20: 1 | I20: 45689 | J20: 45838
E21: 出図進捗 | F21: 出図状況 | G21: 宮崎 | H21: 1 | I21: 45698 | J21: 45709
E22: 製作品納期 | F22: Production Control | G22: 製造管理 | H22: 1 | I22: 45839 | J22: 45869
E23: 組立図進捗 | F23: 出図状況 | G23: ー | H23: 1 | I23: 45839 | J23: 45869
E24: 神戸納入予定日 | F24: Production Control | G24: 製造管理 | H24: 1 | I24: 45839 | J24: 45869
E25: 艤装出図進捗 | F25: 出図状況 | G25: 電気技術 | H25: 1 | I25: 45778 | J25: 45808
E26: 製作品納期 | F26: Production Control | G26: 製造管理 | H26: 1 | I26: 45717 | J26: 45874
E27: 艤装組立図進捗 | F27: 出図状況 | G27: 電気技術 | H27: 1 | I27: 45782 | J27: 45869
E28: 神戸納入予定日 | F28: Production Control | G28: 製造管理 | H28: 1 | I28: 45839 | J28: 45869
E29: 最終電気図面 | F29: 電気工程会議議事録 | G29: 電気技術 | H29: 1 | I29: 45809 | J29: 45818
C30: EN | D30: ー | E30: 盤組立 | F30: 組立工程表 | G30: 守時 | H30: 1 | I30: 45873 | J30: 45891
C31: FL | D31: ー | E31: 盤組立 | G31: 守時 | H31: 1 | I31: 45887 | J31: 45898
E32: 組立期間 | G32: ー | H32: 1 | I32: 45887 | J32: 45940
E33: 塗装 | H33: 1 | I33: 45879 | J33: 45889
E34: 組立 | H34: 1 | I34: 45879 | J34: 45889
E35: 据付 | H35: 1 | I35: 45879 | J35: 45889
C36: FL | D36: ー | E36: 組立 | G36: 米澤 | H36: 1 | I36: 45887 | J36: 46003
D37: ー | E37: 電気艤装 | G37: 木村(至) | H37: 1 | I37: 45985 | J37: 46003
C38: SW | D38: ー | E38: 組立 | G38: 桂/長谷川 | H38: 1 | I38: 45887 | J38: 46003
D39: ー | E39: 電気艤装 | G39: 木村(至) | H39: 1 | I39: 45992 | J39: 46010
C40: UC | D40: ー | E40: 組立 | G40: 桂 | H40: 1 | I40: 45887 | J40: 46017
D41: ー | E41: 電気艤装 | G41: 木村(至) | H41: 1 | I41: 45992 | J41: 46017
...

Sheet 具体例 (2)
C2: 工事番号 | D2: 大項目 | E2: 項目 | F2: 機械 | G2: ユニット | H2: 担当者 | I2: 達成率 | J2: リンク先 | K2: 開始日 | L2: 終了日 | M2: 2024年 | AQ2: 2024年 | BV2: 2025年 | DA2: 2025年 | EC2: 2025年 | FH2: 2025年 | GL2: 2025年 | HQ2: 2025年 | IU2: 2025年 | JZ2: 2025年 | LE2: 2025年 | MI2: 2025年 | NN2: 2025年 | OR2: 2025年 | PW2: 2026年 | RB2: 2026年
M3: 11月 | AQ3: 12月 | BV3: 1月 | DA3: 2月 | EC3: 3月 | FH3: 4月 | GL3: 5月 | HQ3: 6月 | IU3: 7月 | JZ3: 8月 | LE3: 9月 | MI3: 10月 | NN3: 11月 | OR3: 12月 | PW3: 1月 | RB3: 2月
M4: =+_xlfn.XLOOKUP("月",M$7,M$6,0) -> 0 | N4: =+_xlfn.XLOOKUP("月",N$7,N$6,0) -> 0 | O4: =+_xlfn.XLOOKUP("月",O$7,O$6,0) -> 0 | P4: =+_xlfn.XLOOKUP("月",P$7,P$6,0) -> 4 | Q4: =+_xlfn.XLOOKUP("月",Q$7,Q$6,0) -> 0 | R4: =+_xlfn.XLOOKUP("月",R$7,R$6,0) -> 0 | S4: =+_xlfn.XLOOKUP("月",S$7,S$6,0) -> 0 | T4: =+_xlfn.XLOOKUP("月",T$7,T$6,0) -> 0 | ... SC4: =+_xlfn.XLOOKUP("月",SC$7,SC$6,0) -> 0
M5: 45597 | N5: 45598 | O5: 45599 | P5: 45600 | Q5: 45601 | R5: 45602 | S5: 45603 | T5: 45604 | U5: 45605 | V5: 45606 | W5: 45607 | X5: 45608 | Y5: 45609 | Z5: 45610 | AA5: 45611 | AB5: 45612 | AC5: 45613 | AD5: 45614 | AE5: 45615 | AF5: 45616 | AG5: 45617 | AH5: 45618 | AI5: 45619 | AJ5: 45620 | AK5: 45621 | AL5: 45622 | AM5: 45623 | AN5: 45624 | AO5: 45625 | AP5: 45626 | AQ5: 45627 | AR5: 45628 | AS5: 45629 | AT5: 45630 | AU5: 45631 | AV5: 45632 | AW5: 45633 | AX5: 45634 | AY5: 45635 | AZ5: 45636 | BA5: 45637 | BB5: 45638 | BC5: 45639 | BD5: 45640 | BE5: 45641 | BF5: 45642 | BG5: 45643 | BH5: 45644 | BI5: 45645 | BJ5: 45646 | BK5: 45647 | BL5: 45648 | BM5: 45649 | BN5: 45650 | BO5: 45651 | BP5: 45652 | BQ5: 45653 | BR5: 45654 | BS5: 45655 | BT5: 45656 | BU5: 45657 | BV5: 45658 | BW5: 45659 | BX5: 45660 | BY5: 45661 | BZ5: 45662 | CA5: 45663 | CB5: 45664 | CC5: 45665 | CD5: 45666 | CE5: 45667 | CF5: 45668 | CG5: 45669 | CH5: 45670 | CI5: 45671 | CJ5: 45672 | CK5: 45673 | CL5: 45674 | CM5: 45675 | CN5: 45676 | CO5: 45677 | CP5: 45678 | CQ5: 45679 | CR5: 45680 | CS5: 45681 | CT5: 45682 | CU5: 45683 | CV5: 45684 | CW5: 45685 | CX5: 45686 | CY5: 45687 | CZ5: 45688 | DA5: 45689 | DB5: 45690 | DC5: 45691 | DD5: 45692 | DE5: 45693 | DF5: 45694 | DG5: 45695 | DH5: 45696 | DI5: 45697 | DJ5: 45698 | DK5: 45699 | DL5: 45700 | DM5: 45701 | DN5: 45702 | DO5: 45703 | DP5: 45704 | DQ5: 45705 | DR5: 45706 | DS5: 45707 | DT5: 45708 | DU5: 45709 | DV5: 45710 | DW5: 45711 | DX5: 45712 | DY5: 45713 | DZ5: 45714 | EA5: 45715 | EB5: 45716 | EC5: 45717 | ED5: 45718 | EE5: 45719 | EF5: 45720 | EG5: 45721 | EH5: 45722 | EI5: 45723 | EJ5: 45724 | EK5: 45725 | EL5: 45726 | EM5: 45727 | EN5: 45728 | EO5: 45729 | EP5: 45730 | EQ5: 45731 | ER5: 45732 | ES5: 45733 | ET5: 45734 | EU5: 45735 | EV5: 45736 | EW5: 45737 | EX5: 45738 | EY5: 45739 | EZ5: 45740 | FA5: 45741 | FB5: 45742 | FC5: 45743 | FD5: 45744 | FE5: 45745 | FF5: 45746 | FG5: 45747 | FH5: 45748 | FI5: 45749 | FJ5: 45750 | FK5: 45751 | FL5: 45752 | FM5: 45753 | FN5: 45754 | FO5: 45755 | FP5: 45756 | FQ5: 45757 | FR5: 45758 | FS5: 45759 | FT5: 45760 | FU5: 45761 | FV5: 45762 | FW5: 45763 | FX5: 45764 | FY5: 45765 | FZ5: 45766 | GA5: 45767 | GB5: 45768 | GC5: 45769 | GD5: 45770 | GE5: 45771 | GF5: 45772 | GG5: 45773 | GH5: 45774 | GI5: 45775 | GJ5: 45776 | GK5: 45777 | GL5: 45778 | GM5: 45779 | GN5: 45780 | GO5: 45781 | GP5: 45782 | GQ5: 45783 | GR5: 45784 | GS5: 45785 | GT5: 45786 | GU5: 45787 | GV5: 45788 | GW5: 45789 | GX5: 45790 | GY5: 45791 | GZ5: 45792 | HA5: 45793 | HB5: 45794 | HC5: 45795 | HD5: 45796 | HE5: 45797 | HF5: 45798 | HG5: 45799 | HH5: 45800 | HI5: 45801 | HJ5: 45802 | HK5: 45803 | HL5: 45804 | HM5: 45805 | HN5: 45806 | HO5: 45807 | HP5: 45808 | HQ5: 45809 | HR5: 45810 | HS5: 45811 | HT5: 45812 | HU5: 45813 | HV5: 45814 | HW5: 45815 | HX5: 45816 | HY5: 45817 | HZ5: 45818 | IA5: 45819 | IB5: 45820 | IC5: 45821 | ID5: 45822 | IE5: 45823 | IF5: 45824 | IG5: 45825 | IH5: 45826 | II5: 45827 | IJ5: 45828 | IK5: 45829 | IL5: 45830 | IM5: 45831 | IN5: 45832 | IO5: 45833 | IP5: 45834 | IQ5: 45835 | IR5: 45836 | IS5: 45837 | IT5: 45838 | IU5: 45839 | IV5: 45840 | IW5: 45841 | IX5: 45842 | IY5: 45843 | IZ5: 45844 | JA5: 45845 | JB5: 45846 | JC5: 45847 | JD5: 45848 | JE5: 45849 | JF5: 45850 | JG5: 45851 | JH5: 45852 | JI5: 45853 | JJ5: 45854 | JK5: 45855 | JL5: 45856 | JM5: 45857 | JN5: 45858 | JO5: 45859 | JP5: 45860 | JQ5: 45861 | JR5: 45862 | JS5: 45863 | JT5: 45864 | JU5: 45865 | JV5: 45866 | JW5: 45867 | JX5: 45868 | JY5: 45869 | JZ5: 45870 | KA5: 45871 | KB5: 45872 | KC5: 45873 | KD5: 45874 | KE5: 45875 | KF5: 45876 | KG5: 45877 | KH5: 45878 | KI5: 45879 | KJ5: 45880 | KK5: 45881 | KL5: 45882 | KM5: 45883 | KN5: 45884 | KO5: 45885 | KP5: 45886 | KQ5: 45887 | KR5: 45888 | KS5: 45889 | KT5: 45890 | KU5: 45891 | KV5: 45892 | KW5: 45893 | KX5: 45894 | KY5: 45895 | KZ5: 45896 | LA5: 45897 | LB5: 45898 | LC5: 45899 | LD5: 45900 | LE5: 45901 | LF5: 45902 | LG5: 45903 | LH5: 45904 | LI5: 45905 | LJ5: 45906 | LK5: 45907 | LL5: 45908 | LM5: 45909 | LN5: 45910 | LO5: 45911 | LP5: 45912 | LQ5: 45913 | LR5: 45914 | LS5: 45915 | LT5: 45916 | LU5: 45917 | LV5: 45918 | LW5: 45919 | LX5: 45920 | LY5: 45921 | LZ5: 45922 | MA5: 45923 | MB5: 45924 | MC5: 45925 | MD5: 45926 | ME5: 45927 | MF5: 45928 | MG5: 45929 | MH5: 45930 | MI5: 45931 | MJ5: 45932 | MK5: 45933 | ML5: 45934 | MM5: 45935 | MN5: 45936 | MO5: 45937 | MP5: 45938 | MQ5: 45939 | MR5: 45940 | MS5: 45941 | MT5: 45942 | MU5: 45943 | MV5: 45944 | MW5: 45945 | MX5: 45946 | MY5: 45947 | MZ5: 45948 | NA5: 45949 | NB5: 45950 | NC5: 45951 | ND5: 45952 | NE5: 45953 | NF5: 45954 | NG5: 45955 | NH5: 45956 | NI5: 45957 | NJ5: 45958 | NK5: 45959 | NL5: 45960 | NM5: 45961 | NN5: 45962 | NO5: 45963 | NP5: 45964 | NQ5: 45965 | NR5: 45966 | NS5: 45967 | NT5: 45968 | NU5: 45969 | NV5: 45970 | NW5: 45971 | NX5: 45972 | NY5: 45973 | NZ5: 45974 | OA5: 45975 | OB5: 45976 | OC5: 45977 | OD5: 45978 | OE5: 45979 | OF5: 45980 | OG5: 45981 | OH5: 45982 | OI5: 45983 | OJ5: 45984 | OK5: 45985 | OL5: 45986 | OM5: 45987 | ON5: 45988 | OO5: 45989 | OP5: 45990 | OQ5: 45991 | OR5: 45992 | OS5: 45993 | OT5: 45994 | OU5: 45995 | OV5: 45996 | OW5: 45997 | OX5: 45998 | OY5: 45999 | OZ5: 46000 | PA5: 46001 | PB5: 46002 | PC5: 46003 | PD5: 46004 | PE5: 46005 | PF5: 46006 | PG5: 46007 | PH5: 46008 | PI5: 46009 | PJ5: 46010 | PK5: 46011 | PL5: 46012 | PM5: 46013 | PN5: 46014 | PO5: 46015 | PP5: 46016 | PQ5: 46017 | PR5: 46018 | PS5: 46019 | PT5: 46020 | PU5: 46021 | PV5: 46022 | PW5: 46023 | PX5: 46024 | PY5: 46025 | PZ5: 46026 | QA5: 46027 | QB5: 46028 | QC5: 46029 | QD5: 46030 | QE5: 46031 | QF5: 46032 | QG5: 46033 | QH5: 46034 | QI5: 46035 | QJ5: 46036 | QK5: 46037 | QL5: 46038 | QM5: 46039 | QN5: 46040 | QO5: 46041 | QP5: 46042 | QQ5: 46043 | QR5: 46044 | QS5: 46045 | QT5: 46046 | QU5: 46047 | QV5: 46048 | QW5: 46049 | QX5: 46050 | QY5: 46051 | QZ5: 46052 | RA5: 46053 | RB5: 46054 | RC5: 46055 | RD5: 46056 | RE5: 46057 | RF5: 46058 | RG5: 46059 | RH5: 46060 | RI5: 46061 | RJ5: 46062 | RK5: 46063 | RL5: 46064 | RM5: 46065 | RN5: 46066 | RO5: 46067 | RP5: 46068 | RQ5: 46069 | RR5: 46070 | RS5: 46071 | RT5: 46072 | RU5: 46073 | RV5: 46074 | RW5: 46075 | RX5: 46076 | RY5: 46077 | RZ5: 46078 | SA5: 46079 | SB5: 46080 | SC5: 46081
M6: 1 | N6: =+M6+1 -> 2 | O6: =+N6+1 -> 3 | P6: =+O6+1 -> 4 | Q6: =+P6+1 -> 5 | R6: =+Q6+1 -> 6 | S6: =+R6+1 -> 7 | T6: =+S6+1 -> 8 | U6: =+T6+1 -> 9 | ... AP6: =+AO6+1 -> 30 | AQ6: 1 | AR6: =+AQ6+1 -> 2 | AS6: =+AR6+1 -> 3 | AT6: =+AS6+1 -> 4 | AU6: =+AT6+1 -> 5 | AV6: =+AU6+1 -> 6 | AW6: =+AV6+1 -> 7 | AX6: =+AW6+1 -> 8 | AY6: =+AX6+1 -> 9 | ... BU6: =+BT6+1 -> 31 | BV6: 1 | BW6: =+BV6+1 -> 2 | BX6: =+BW6+1 -> 3 | BY6: =+BX6+1 -> 4 | BZ6: =+BY6+1 -> 5 | CA6: =+BZ6+1 -> 6 | CB6: =+CA6+1 -> 7 | CC6: =+CB6+1 -> 8 | CD6: =+CC6+1 -> 9 | ... CZ6: =+CY6+1 -> 31 | DA6: 1 | DB6: =+DA6+1 -> 2 | DC6: =+DB6+1 -> 3 | DD6: =+DC6+1 -> 4 | DE6: =+DD6+1 -> 5 | DF6: =+DE6+1 -> 6 | DG6: =+DF6+1 -> 7 | DH6: =+DG6+1 -> 8 | DI6: =+DH6+1 -> 9 | ... EB6: =+EA6+1 -> 28 | EC6: 1 | ED6: =+EC6+1 -> 2 | EE6: =+ED6+1 -> 3 | EF6: =+EE6+1 -> 4 | EG6: =+EF6+1 -> 5 | EH6: =+EG6+1 -> 6 | EI6: =+EH6+1 -> 7 | EJ6: =+EI6+1 -> 8 | EK6: =+EJ6+1 -> 9 | ... FG6: =+FF6+1 -> 31 | FH6: 1 | FI6: =+FH6+1 -> 2 | FJ6: =+FI6+1 -> 3 | FK6: =+FJ6+1 -> 4 | FL6: =+FK6+1 -> 5 | FM6: =+FL6+1 -> 6 | FN6: =+FM6+1 -> 7 | FO6: =+FN6+1 -> 8 | FP6: =+FO6+1 -> 9 | ... GK6: =+GJ6+1 -> 30 | GL6: 1 | GM6: =+GL6+1 -> 2 | GN6: =+GM6+1 -> 3 | GO6: =+GN6+1 -> 4 | GP6: =+GO6+1 -> 5 | GQ6: =+GP6+1 -> 6 | GR6: =+GQ6+1 -> 7 | GS6: =+GR6+1 -> 8 | GT6: =+GS6+1 -> 9 | ... HP6: =+HO6+1 -> 31 | HQ6: 1 | HR6: =+HQ6+1 -> 2 | HS6: =+HR6+1 -> 3 | HT6: =+HS6+1 -> 4 | HU6: =+HT6+1 -> 5 | HV6: =+HU6+1 -> 6 | HW6: =+HV6+1 -> 7 | HX6: =+HW6+1 -> 8 | HY6: =+HX6+1 -> 9 | ... IT6: =+IS6+1 -> 30 | IU6: 1 | IV6: =+IU6+1 -> 2 | IW6: =+IV6+1 -> 3 | IX6: =+IW6+1 -> 4 | IY6: =+IX6+1 -> 5 | IZ6: =+IY6+1 -> 6 | JA6: =+IZ6+1 -> 7 | JB6: =+JA6+1 -> 8 | JC6: =+JB6+1 -> 9 | ... JY6: =+JX6+1 -> 31 | JZ6: 1 | KA6: =+JZ6+1 -> 2 | KB6: =+KA6+1 -> 3 | KC6: =+KB6+1 -> 4 | KD6: =+KC6+1 -> 5 | KE6: =+KD6+1 -> 6 | KF6: =+KE6+1 -> 7 | KG6: =+KF6+1 -> 8 | KH6: =+KG6+1 -> 9 | ... LD6: =+LC6+1 -> 31 | LE6: 1 | LF6: =+LE6+1 -> 2 | LG6: =+LF6+1 -> 3 | LH6: =+LG6+1 -> 4 | LI6: =+LH6+1 -> 5 | LJ6: =+LI6+1 -> 6 | LK6: =+LJ6+1 -> 7 | LL6: =+LK6+1 -> 8 | LM6: =+LL6+1 -> 9 | ... MH6: =+MG6+1 -> 30 | MI6: 1 | MJ6: =+MI6+1 -> 2 | MK6: =+MJ6+1 -> 3 | ML6: =+MK6+1 -> 4 | MM6: =+ML6+1 -> 5 | MN6: =+MM6+1 -> 6 | MO6: =+MN6+1 -> 7 | MP6: =+MO6+1 -> 8 | MQ6: =+MP6+1 -> 9 | ... NM6: =+NL6+1 -> 31 | NN6: 1 | NO6: =+NN6+1 -> 2 | NP6: =+NO6+1 -> 3 | NQ6: =+NP6+1 -> 4 | NR6: =+NQ6+1 -> 5 | NS6: =+NR6+1 -> 6 | NT6: =+NS6+1 -> 7 | NU6: =+NT6+1 -> 8 | NV6: =+NU6+1 -> 9 | ... OQ6: =+OP6+1 -> 30 | OR6: 1 | OS6: =+OR6+1 -> 2 | OT6: =+OS6+1 -> 3 | OU6: =+OT6+1 -> 4 | OV6: =+OU6+1 -> 5 | OW6: =+OV6+1 -> 6 | OX6: =+OW6+1 -> 7 | OY6: =+OX6+1 -> 8 | OZ6: =+OY6+1 -> 9 | ... PV6: =+PU6+1 -> 31 | PW6: 1 | PX6: =+PW6+1 -> 2 | PY6: =+PX6+1 -> 3 | PZ6: =+PY6+1 -> 4 | QA6: =+PZ6+1 -> 5 | QB6: =+QA6+1 -> 6 | QC6: =+QB6+1 -> 7 | QD6: =+QC6+1 -> 8 | QE6: =+QD6+1 -> 9 | ... RA6: =+QZ6+1 -> 31 | RB6: 1 | RC6: =+RB6+1 -> 2 | RD6: =+RC6+1 -> 3 | RE6: =+RD6+1 -> 4 | RF6: =+RE6+1 -> 5 | RG6: =+RF6+1 -> 6 | RH6: =+RG6+1 -> 7 | RI6: =+RH6+1 -> 8 | RJ6: =+RI6+1 -> 9 | ... SC6: =+SB6+1 -> 28
M7: 金 | N7: 土 | O7: 日 | P7: 月 | Q7: 火 | R7: 水 | S7: 木 | T7: 金 | U7: 土 | V7: 日 | W7: 月 | X7: 火 | Y7: 水 | Z7: 木 | AA7: 金 | AB7: 土 | AC7: 日 | AD7: 月 | AE7: 火 | AF7: 水 | AG7: 木 | AH7: 金 | AI7: 土 | AJ7: 日 | AK7: 月 | AL7: 火 | AM7: 水 | AN7: 木 | AO7: 金 | AP7: 土 | AQ7: 日 | AR7: 月 | AS7: 火 | AT7: 水 | AU7: 木 | AV7: 金 | AW7: 土 | AX7: 日 | AY7: 月 | AZ7: 火 | BA7: 水 | BB7: 木 | BC7: 金 | BD7: 土 | BE7: 日 | BF7: 月 | BG7: 火 | BH7: 水 | BI7: 木 | BJ7: 金 | BK7: 土 | BL7: 日 | BM7: 月 | BN7: 火 | BO7: 水 | BP7: 木 | BQ7: 金 | BR7: 土 | BS7: 日 | BT7: 月 | BU7: 火 | BV7: 水 | BW7: 木 | BX7: 金 | BY7: 土 | BZ7: 日 | CA7: 月 | CB7: 火 | CC7: 水 | CD7: 木 | CE7: 金 | CF7: 土 | CG7: 日 | CH7: 月 | CI7: 火 | CJ7: 水 | CK7: 木 | CL7: 金 | CM7: 土 | CN7: 日 | CO7: 月 | CP7: 火 | CQ7: 水 | CR7: 木 | CS7: 金 | CT7: 土 | CU7: 日 | CV7: 月 | CW7: 火 | CX7: 水 | CY7: 木 | CZ7: 金 | DA7: 土 | DB7: 日 | DC7: 月 | DD7: 火 | DE7: 水 | DF7: 木 | DG7: 金 | DH7: 土 | DI7: 日 | DJ7: 月 | DK7: 火 | DL7: 水 | DM7: 木 | DN7: 金 | DO7: 土 | DP7: 日 | DQ7: 月 | DR7: 火 | DS7: 水 | DT7: 木 | DU7: 金 | DV7: 土 | DW7: 日 | DX7: 月 | DY7: 火 | DZ7: 水 | EA7: 木 | EB7: 金 | EC7: 土 | ED7: 日 | EE7: 月 | EF7: 火 | EG7: 水 | EH7: 木 | EI7: 金 | EJ7: 土 | EK7: 日 | EL7: 月 | EM7: 火 | EN7: 水 | EO7: 木 | EP7: 金 | EQ7: 土 | ER7: 日 | ES7: 月 | ET7: 火 | EU7: 水 | EV7: 木 | EW7: 金 | EX7: 土 | EY7: 日 | EZ7: 月 | FA7: 火 | FB7: 水 | FC7: 木 | FD7: 金 | FE7: 土 | FF7: 日 | FG7: 月 | FH7: 火 | FI7: 水 | FJ7: 木 | FK7: 金 | FL7: 土 | FM7: 日 | FN7: 月 | FO7: 火 | FP7: 水 | FQ7: 木 | FR7: 金 | FS7: 土 | FT7: 日 | FU7: 月 | FV7: 火 | FW7: 水 | FX7: 木 | FY7: 金 | FZ7: 土 | GA7: 日 | GB7: 月 | GC7: 火 | GD7: 水 | GE7: 木 | GF7: 金 | GG7: 土 | GH7: 日 | GI7: 月 | GJ7: 火 | GK7: 水 | GL7: 木 | GM7: 金 | GN7: 土 | GO7: 日 | GP7: 月 | GQ7: 火 | GR7: 水 | GS7: 木 | GT7: 金 | GU7: 土 | GV7: 日 | GW7: 月 | GX7: 火 | GY7: 水 | GZ7: 木 | HA7: 金 | HB7: 土 | HC7: 日 | HD7: 月 | HE7: 火 | HF7: 水 | HG7: 木 | HH7: 金 | HI7: 土 | HJ7: 日 | HK7: 月 | HL7: 火 | HM7: 水 | HN7: 木 | HO7: 金 | HP7: 土 | HQ7: 日 | HR7: 月 | HS7: 火 | HT7: 水 | HU7: 木 | HV7: 金 | HW7: 土 | HX7: 日 | HY7: 月 | HZ7: 火 | IA7: 水 | IB7: 木 | IC7: 金 | ID7: 土 | IE7: 日 | IF7: 月 | IG7: 火 | IH7: 水 | II7: 木 | IJ7: 金 | IK7: 土 | IL7: 日 | IM7: 月 | IN7: 火 | IO7: 水 | IP7: 木 | IQ7: 金 | IR7: 土 | IS7: 日 | IT7: 月 | IU7: 火 | IV7: 水 | IW7: 木 | IX7: 金 | IY7: 土 | IZ7: 日 | JA7: 月 | JB7: 火 | JC7: 水 | JD7: 木 | JE7: 金 | JF7: 土 | JG7: 日 | JH7: 月 | JI7: 火 | JJ7: 水 | JK7: 木 | JL7: 金 | JM7: 土 | JN7: 日 | JO7: 月 | JP7: 火 | JQ7: 水 | JR7: 木 | JS7: 金 | JT7: 土 | JU7: 日 | JV7: 月 | JW7: 火 | JX7: 水 | JY7: 木 | JZ7: 金 | KA7: 土 | KB7: 日 | KC7: 月 | KD7: 火 | KE7: 水 | KF7: 木 | KG7: 金 | KH7: 土 | KI7: 日 | KJ7: 月 | KK7: 火 | KL7: 水 | KM7: 木 | KN7: 金 | KO7: 土 | KP7: 日 | KQ7: 月 | KR7: 火 | KS7: 水 | KT7: 木 | KU7: 金 | KV7: 土 | KW7: 日 | KX7: 月 | KY7: 火 | KZ7: 水 | LA7: 木 | LB7: 金 | LC7: 土 | LD7: 日 | LE7: 月 | LF7: 火 | LG7: 水 | LH7: 木 | LI7: 金 | LJ7: 土 | LK7: 日 | LL7: 月 | LM7: 火 | LN7: 水 | LO7: 木 | LP7: 金 | LQ7: 土 | LR7: 日 | LS7: 月 | LT7: 火 | LU7: 水 | LV7: 木 | LW7: 金 | LX7: 土 | LY7: 日 | LZ7: 月 | MA7: 火 | MB7: 水 | MC7: 木 | MD7: 金 | ME7: 土 | MF7: 日 | MG7: 月 | MH7: 火 | MI7: 水 | MJ7: 木 | MK7: 金 | ML7: 土 | MM7: 日 | MN7: 月 | MO7: 火 | MP7: 水 | MQ7: 木 | MR7: 金 | MS7: 土 | MT7: 日 | MU7: 月 | MV7: 火 | MW7: 水 | MX7: 木 | MY7: 金 | MZ7: 土 | NA7: 日 | NB7: 月 | NC7: 火 | ND7: 水 | NE7: 木 | NF7: 金 | NG7: 土 | NH7: 日 | NI7: 月 | NJ7: 火 | NK7: 水 | NL7: 木 | NM7: 金 | NN7: 土 | NO7: 日 | NP7: 月 | NQ7: 火 | NR7: 水 | NS7: 木 | NT7: 金 | NU7: 土 | NV7: 日 | NW7: 月 | NX7: 火 | NY7: 水 | NZ7: 木 | OA7: 金 | OB7: 土 | OC7: 日 | OD7: 月 | OE7: 火 | OF7: 水 | OG7: 木 | OH7: 金 | OI7: 土 | OJ7: 日 | OK7: 月 | OL7: 火 | OM7: 水 | ON7: 木 | OO7: 金 | OP7: 土 | OQ7: 日 | OR7: 月 | OS7: 火 | OT7: 水 | OU7: 木 | OV7: 金 | OW7: 土 | OX7: 日 | OY7: 月 | OZ7: 火 | PA7: 水 | PB7: 木 | PC7: 金 | PD7: 土 | PE7: 日 | PF7: 月 | PG7: 火 | PH7: 水 | PI7: 木 | PJ7: 金 | PK7: 土 | PL7: 日 | PM7: 月 | PN7: 火 | PO7: 水 | PP7: 木 | PQ7: 金 | PR7: 土 | PS7: 日 | PT7: 月 | PU7: 火 | PV7: 水 | PW7: 木 | PX7: 金 | PY7: 土 | PZ7: 日 | QA7: 月 | QB7: 火 | QC7: 水 | QD7: 木 | QE7: 金 | QF7: 土 | QG7: 日 | QH7: 月 | QI7: 火 | QJ7: 水 | QK7: 木 | QL7: 金 | QM7: 土 | QN7: 日 | QO7: 月 | QP7: 火 | QQ7: 水 | QR7: 木 | QS7: 金 | QT7: 土 | QU7: 日 | QV7: 月 | QW7: 火 | QX7: 水 | QY7: 木 | QZ7: 金 | RA7: 土 | RB7: 日 | RC7: 月 | RD7: 火 | RE7: 水 | RF7: 木 | RG7: 金 | RH7: 土 | RI7: 日 | RJ7: 月 | RK7: 火 | RL7: 水 | RM7: 木 | RN7: 金 | RO7: 土 | RP7: 日 | RQ7: 月 | RR7: 火 | RS7: 水 | RT7: 木 | RU7: 金 | RV7: 土 | RW7: 日 | RX7: 月 | RY7: 火 | RZ7: 水 | SA7: 木 | SB7: 金 | SC7: 土
B8: 2809 | C8: 2809 | D8: 受注 | E8: 受注説明会 | F8: 全て | G8: ー | H8: 岡本 | I8: 完了 | J8: 社内製作仕様書 | K8: 45597 | L8: 45597 | M8: =IF(AND(M$5>=$K8, M$5<=$L8, WEEKDAY(M$5, 2)<6), LEFT($H8, 1), "") -> 岡 | N8: =IF(AND(N$5>=$K8, N$5<=$L8, WEEKDAY(N$5, 2)<6), LEFT($H8, 1), "") | O8: =IF(AND(O$5>=$K8, O$5<=$L8, WEEKDAY(O$5, 2)<6), LEFT($H8, 1), "") | P8: =IF(AND(P$5>=$K8, P$5<=$L8, WEEKDAY(P$5, 2)<6), LEFT($H8, 1), "") | Q8: =IF(AND(Q$5>=$K8, Q$5<=$L8, WEEKDAY(Q$5, 2)<6), LEFT($H8, 1), "") | R8: =IF(AND(R$5>=$K8, R$5<=$L8, WEEKDAY(R$5, 2)<6), LEFT($H8, 1), "") | S8: =IF(AND(S$5>=$K8, S$5<=$L8, WEEKDAY(S$5, 2)<6), LEFT($H8, 1), "") | T8: =IF(AND(T$5>=$K8, T$5<=$L8, WEEKDAY(T$5, 2)<6), LEFT($H8, 1), "") | ... SC8: =IF(AND(SC$5>=$K8, SC$5<=$L8, WEEKDAY(SC$5, 2)<6), LEFT($H8, 1), "")
B9: 2809 | D9: 計画・承認 | E9: 計画設計 | H9: 宮崎 | I9: 完了 | J9: 出図状況 | K9: 45622 | L9: 45622 | M9: =IF(AND(M$5>=$K9, M$5<=$L9, WEEKDAY(M$5, 2)<6), LEFT($H9, 1), "") | N9: =IF(AND(N$5>=$K9, N$5<=$L9, WEEKDAY(N$5, 2)<6), LEFT($H9, 1), "") | O9: =IF(AND(O$5>=$K9, O$5<=$L9, WEEKDAY(O$5, 2)<6), LEFT($H9, 1), "") | P9: =IF(AND(P$5>=$K9, P$5<=$L9, WEEKDAY(P$5, 2)<6), LEFT($H9, 1), "") | Q9: =IF(AND(Q$5>=$K9, Q$5<=$L9, WEEKDAY(Q$5, 2)<6), LEFT($H9, 1), "") | R9: =IF(AND(R$5>=$K9, R$5<=$L9, WEEKDAY(R$5, 2)<6), LEFT($H9, 1), "") | S9: =IF(AND(S$5>=$K9, S$5<=$L9, WEEKDAY(S$5, 2)<6), LEFT($H9, 1), "") | T9: =IF(AND(T$5>=$K9, T$5<=$L9, WEEKDAY(T$5, 2)<6), LEFT($H9, 1), "") | ... SC9: =IF(AND(SC$5>=$K9, SC$5<=$L9, WEEKDAY(SC$5, 2)<6), LEFT($H9, 1), "")
B10: 2809 | E10: 計画図客先提出 | H10: 岡本 | I10: 完了 | K10: 45623 | L10: 45632 | M10: =IF(AND(M$5>=$K10, M$5<=$L10, WEEKDAY(M$5, 2)<6), LEFT($H10, 1), "") | N10: =IF(AND(N$5>=$K10, N$5<=$L10, WEEKDAY(N$5, 2)<6), LEFT($H10, 1), "") | O10: =IF(AND(O$5>=$K10, O$5<=$L10, WEEKDAY(O$5, 2)<6), LEFT($H10, 1), "") | P10: =IF(AND(P$5>=$K10, P$5<=$L10, WEEKDAY(P$5, 2)<6), LEFT($H10, 1), "") | Q10: =IF(AND(Q$5>=$K10, Q$5<=$L10, WEEKDAY(Q$5, 2)<6), LEFT($H10, 1), "") | R10: =IF(AND(R$5>=$K10, R$5<=$L10, WEEKDAY(R$5, 2)<6), LEFT($H10, 1), "") | S10: =IF(AND(S$5>=$K10, S$5<=$L10, WEEKDAY(S$5, 2)<6), LEFT($H10, 1), "") | T10: =IF(AND(T$5>=$K10, T$5<=$L10, WEEKDAY(T$5, 2)<6), LEFT($H10, 1), "") | ... SC10: =IF(AND(SC$5>=$K10, SC$5<=$L10, WEEKDAY(SC$5, 2)<6), LEFT($H10, 1), "")
B11: 2809 | E11: 客先承認 | H11: ー | I11: 完了 | K11: 45635 | L11: 45646 | M11: =IF(AND(M$5>=$K11, M$5<=$L11, WEEKDAY(M$5, 2)<6), LEFT($H11, 1), "") | N11: =IF(AND(N$5>=$K11, N$5<=$L11, WEEKDAY(N$5, 2)<6), LEFT($H11, 1), "") | O11: =IF(AND(O$5>=$K11, O$5<=$L11, WEEKDAY(O$5, 2)<6), LEFT($H11, 1), "") | P11: =IF(AND(P$5>=$K11, P$5<=$L11, WEEKDAY(P$5, 2)<6), LEFT($H11, 1), "") | Q11: =IF(AND(Q$5>=$K11, Q$5<=$L11, WEEKDAY(Q$5, 2)<6), LEFT($H11, 1), "") | R11: =IF(AND(R$5>=$K11, R$5<=$L11, WEEKDAY(R$5, 2)<6), LEFT($H11, 1), "") | S11: =IF(AND(S$5>=$K11, S$5<=$L11, WEEKDAY(S$5, 2)<6), LEFT($H11, 1), "") | T11: =IF(AND(T$5>=$K11, T$5<=$L11, WEEKDAY(T$5, 2)<6), LEFT($H11, 1), "") | ... SC11: =IF(AND(SC$5>=$K11, SC$5<=$L11, WEEKDAY(SC$5, 2)<6), LEFT($H11, 1), "")
B12: 2809 | E12: 操作盤外形図検討 | H12: 電気技術 | I12: 完了 | J12: 電気工程会議 | K12: 45649 | L12: 45653 | M12: =IF(AND(M$5>=$K12, M$5<=$L12, WEEKDAY(M$5, 2)<6), LEFT($H12, 1), "") | N12: =IF(AND(N$5>=$K12, N$5<=$L12, WEEKDAY(N$5, 2)<6), LEFT($H12, 1), "") | O12: =IF(AND(O$5>=$K12, O$5<=$L12, WEEKDAY(O$5, 2)<6), LEFT($H12, 1), "") | P12: =IF(AND(P$5>=$K12, P$5<=$L12, WEEKDAY(P$5, 2)<6), LEFT($H12, 1), "") | Q12: =IF(AND(Q$5>=$K12, Q$5<=$L12, WEEKDAY(Q$5, 2)<6), LEFT($H12, 1), "") | R12: =IF(AND(R$5>=$K12, R$5<=$L12, WEEKDAY(R$5, 2)<6), LEFT($H12, 1), "") | S12: =IF(AND(S$5>=$K12, S$5<=$L12, WEEKDAY(S$5, 2)<6), LEFT($H12, 1), "") | T12: =IF(AND(T$5>=$K12, T$5<=$L12, WEEKDAY(T$5, 2)<6), LEFT($H12, 1), "") | ... SC12: =IF(AND(SC$5>=$K12, SC$5<=$L12, WEEKDAY(SC$5, 2)<6), LEFT($H12, 1), "")
B13: 2809 | E13: 外形図客先提出 | H13: 電気技術 | I13: 完了 | K13: 45663 | L13: 45667 | M13: =IF(AND(M$5>=$K13, M$5<=$L13, WEEKDAY(M$5, 2)<6), LEFT($H13, 1), "") | N13: =IF(AND(N$5>=$K13, N$5<=$L13, WEEKDAY(N$5, 2)<6), LEFT($H13, 1), "") | O13: =IF(AND(O$5>=$K13, O$5<=$L13, WEEKDAY(O$5, 2)<6), LEFT($H13, 1), "") | P13: =IF(AND(P$5>=$K13, P$5<=$L13, WEEKDAY(P$5, 2)<6), LEFT($H13, 1), "") | Q13: =IF(AND(Q$5>=$K13, Q$5<=$L13, WEEKDAY(Q$5, 2)<6), LEFT($H13, 1), "") | R13: =IF(AND(R$5>=$K13, R$5<=$L13, WEEKDAY(R$5, 2)<6), LEFT($H13, 1), "") | S13: =IF(AND(S$5>=$K13, S$5<=$L13, WEEKDAY(S$5, 2)<6), LEFT($H13, 1), "") | T13: =IF(AND(T$5>=$K13, T$5<=$L13, WEEKDAY(T$5, 2)<6), LEFT($H13, 1), "") | ... SC13: =IF(AND(SC$5>=$K13, SC$5<=$L13, WEEKDAY(SC$5, 2)<6), LEFT($H13, 1), "")
B14: 2809 | E14: 電気図面設計 | H14: 電気技術 | I14: 完了 | K14: 45670 | L14: 45674 | M14: =IF(AND(M$5>=$K14, M$5<=$L14, WEEKDAY(M$5, 2)<6), LEFT($H14, 1), "") | N14: =IF(AND(N$5>=$K14, N$5<=$L14, WEEKDAY(N$5, 2)<6), LEFT($H14, 1), "") | O14: =IF(AND(O$5>=$K14, O$5<=$L14, WEEKDAY(O$5, 2)<6), LEFT($H14, 1), "") | P14: =IF(AND(P$5>=$K14, P$5<=$L14, WEEKDAY(P$5, 2)<6), LEFT($H14, 1), "") | Q14: =IF(AND(Q$5>=$K14, Q$5<=$L14, WEEKDAY(Q$5, 2)<6), LEFT($H14, 1), "") | R14: =IF(AND(R$5>=$K14, R$5<=$L14, WEEKDAY(R$5, 2)<6), LEFT($H14, 1), "") | S14: =IF(AND(S$5>=$K14, S$5<=$L14, WEEKDAY(S$5, 2)<6), LEFT($H14, 1), "") | T14: =IF(AND(T$5>=$K14, T$5<=$L14, WEEKDAY(T$5, 2)<6), LEFT($H14, 1), "") | ... SC14: =IF(AND(SC$5>=$K14, SC$5<=$L14, WEEKDAY(SC$5, 2)<6), LEFT($H14, 1), "")
B15: 2809 | E15: 電気図面客先提出 | H15: 電気技術 | I15: 完了 | K15: 45677 | L15: 45681 | M15: =IF(AND(M$5>=$K15, M$5<=$L15, WEEKDAY(M$5, 2)<6), LEFT($H15, 1), "") | N15: =IF(AND(N$5>=$K15, N$5<=$L15, WEEKDAY(N$5, 2)<6), LEFT($H15, 1), "") | O15: =IF(AND(O$5>=$K15, O$5<=$L15, WEEKDAY(O$5, 2)<6), LEFT($H15, 1), "") | P15: =IF(AND(P$5>=$K15, P$5<=$L15, WEEKDAY(P$5, 2)<6), LEFT($H15, 1), "") | Q15: =IF(AND(Q$5>=$K15, Q$5<=$L15, WEEKDAY(Q$5, 2)<6), LEFT($H15, 1), "") | R15: =IF(AND(R$5>=$K15, R$5<=$L15, WEEKDAY(R$5, 2)<6), LEFT($H15, 1), "") | S15: =IF(AND(S$5>=$K15, S$5<=$L15, WEEKDAY(S$5, 2)<6), LEFT($H15, 1), "") | T15: =IF(AND(T$5>=$K15, T$5<=$L15, WEEKDAY(T$5, 2)<6), LEFT($H15, 1), "") | ... SC15: =IF(AND(SC$5>=$K15, SC$5<=$L15, WEEKDAY(SC$5, 2)<6), LEFT($H15, 1), "")
B16: 2809 | E16: 客先承認 | H16: ー | I16: 完了 | K16: 45684 | L16: 45688 | M16: =IF(AND(M$5>=$K16, M$5<=$L16, WEEKDAY(M$5, 2)<6), LEFT($H16, 1), "") | N16: =IF(AND(N$5>=$K16, N$5<=$L16, WEEKDAY(N$5, 2)<6), LEFT($H16, 1), "") | O16: =IF(AND(O$5>=$K16, O$5<=$L16, WEEKDAY(O$5, 2)<6), LEFT($H16, 1), "") | P16: =IF(AND(P$5>=$K16, P$5<=$L16, WEEKDAY(P$5, 2)<6), LEFT($H16, 1), "") | Q16: =IF(AND(Q$5>=$K16, Q$5<=$L16, WEEKDAY(Q$5, 2)<6), LEFT($H16, 1), "") | R16: =IF(AND(R$5>=$K16, R$5<=$L16, WEEKDAY(R$5, 2)<6), LEFT($H16, 1), "") | S16: =IF(AND(S$5>=$K16, S$5<=$L16, WEEKDAY(S$5, 2)<6), LEFT($H16, 1), "") | T16: =IF(AND(T$5>=$K16, T$5<=$L16, WEEKDAY(T$5, 2)<6), LEFT($H16, 1), "") | ... SC16: =IF(AND(SC$5>=$K16, SC$5<=$L16, WEEKDAY(SC$5, 2)<6), LEFT($H16, 1), "")
B17: 2809 | D17: 手配 | E17: 長納期購入品検討＆手配 | H17: 製造管理 | I17: 完了 | J17: 長納期品手配状況 | K17: 45689 | L17: 45695 | M17: =IF(AND(M$5>=$K17, M$5<=$L17, WEEKDAY(M$5, 2)<6), LEFT($H17, 1), "") | N17: =IF(AND(N$5>=$K17, N$5<=$L17, WEEKDAY(N$5, 2)<6), LEFT($H17, 1), "") | O17: =IF(AND(O$5>=$K17, O$5<=$L17, WEEKDAY(O$5, 2)<6), LEFT($H17, 1), "") | P17: =IF(AND(P$5>=$K17, P$5<=$L17, WEEKDAY(P$5, 2)<6), LEFT($H17, 1), "") | Q17: =IF(AND(Q$5>=$K17, Q$5<=$L17, WEEKDAY(Q$5, 2)<6), LEFT($H17, 1), "") | R17: =IF(AND(R$5>=$K17, R$5<=$L17, WEEKDAY(R$5, 2)<6), LEFT($H17, 1), "") | S17: =IF(AND(S$5>=$K17, S$5<=$L17, WEEKDAY(S$5, 2)<6), LEFT($H17, 1), "") | T17: =IF(AND(T$5>=$K17, T$5<=$L17, WEEKDAY(T$5, 2)<6), LEFT($H17, 1), "") | ... SC17: =IF(AND(SC$5>=$K17, SC$5<=$L17, WEEKDAY(SC$5, 2)<6), LEFT($H17, 1), "")
B18: 2809 | E18: 電気品 筐体手配 | H18: 電気技術 | I18: 完了 | K18: 45698 | L18: 45702 | M18: =IF(AND(M$5>=$K18, M$5<=$L18, WEEKDAY(M$5, 2)<6), LEFT($H18, 1), "") | N18: =IF(AND(N$5>=$K18, N$5<=$L18, WEEKDAY(N$5, 2)<6), LEFT($H18, 1), "") | O18: =IF(AND(O$5>=$K18, O$5<=$L18, WEEKDAY(O$5, 2)<6), LEFT($H18, 1), "") | P18: =IF(AND(P$5>=$K18, P$5<=$L18, WEEKDAY(P$5, 2)<6), LEFT($H18, 1), "") | Q18: =IF(AND(Q$5>=$K18, Q$5<=$L18, WEEKDAY(Q$5, 2)<6), LEFT($H18, 1), "") | R18: =IF(AND(R$5>=$K18, R$5<=$L18, WEEKDAY(R$5, 2)<6), LEFT($H18, 1), "") | S18: =IF(AND(S$5>=$K18, S$5<=$L18, WEEKDAY(S$5, 2)<6), LEFT($H18, 1), "") | T18: =IF(AND(T$5>=$K18, T$5<=$L18, WEEKDAY(T$5, 2)<6), LEFT($H18, 1), "") | ... SC18: =IF(AND(SC$5>=$K18, SC$5<=$L18, WEEKDAY(SC$5, 2)<6), LEFT($H18, 1), "")
B19: 2809 | E19: 長納期製作品手配＆手配 | H19: 製造管理 | I19: 完了 | K19: 45689 | L19: 45838 | M19: =IF(AND(M$5>=$K19, M$5<=$L19, WEEKDAY(M$5, 2)<6), LEFT($H19, 1), "") | N19: =IF(AND(N$5>=$K19, N$5<=$L19, WEEKDAY(N$5, 2)<6), LEFT($H19, 1), "") | O19: =IF(AND(O$5>=$K19, O$5<=$L19, WEEKDAY(O$5, 2)<6), LEFT($H19, 1), "") | P19: =IF(AND(P$5>=$K19, P$5<=$L19, WEEKDAY(P$5, 2)<6), LEFT($H19, 1), "") | Q19: =IF(AND(Q$5>=$K19, Q$5<=$L19, WEEKDAY(Q$5, 2)<6), LEFT($H19, 1), "") | R19: =IF(AND(R$5>=$K19, R$5<=$L19, WEEKDAY(R$5, 2)<6), LEFT($H19, 1), "") | S19: =IF(AND(S$5>=$K19, S$5<=$L19, WEEKDAY(S$5, 2)<6), LEFT($H19, 1), "") | T19: =IF(AND(T$5>=$K19, T$5<=$L19, WEEKDAY(T$5, 2)<6), LEFT($H19, 1), "") | ... SC19: =IF(AND(SC$5>=$K19, SC$5<=$L19, WEEKDAY(SC$5, 2)<6), LEFT($H19, 1), "")
B20: 2809 | D20: 出図 | E20: 出図進捗 | H20: 宮崎 | I20: 完了 | J20: 出図状況 | K20: 45698 | L20: 45709 | M20: =IF(AND(M$5>=$K20, M$5<=$L20, WEEKDAY(M$5, 2)<6), LEFT($H20, 1), "") | N20: =IF(AND(N$5>=$K20, N$5<=$L20, WEEKDAY(N$5, 2)<6), LEFT($H20, 1), "") | O20: =IF(AND(O$5>=$K20, O$5<=$L20, WEEKDAY(O$5, 2)<6), LEFT($H20, 1), "") | P20: =IF(AND(P$5>=$K20, P$5<=$L20, WEEKDAY(P$5, 2)<6), LEFT($H20, 1), "") | Q20: =IF(AND(Q$5>=$K20, Q$5<=$L20, WEEKDAY(Q$5, 2)<6), LEFT($H20, 1), "") | R20: =IF(AND(R$5>=$K20, R$5<=$L20, WEEKDAY(R$5, 2)<6), LEFT($H20, 1), "") | S20: =IF(AND(S$5>=$K20, S$5<=$L20, WEEKDAY(S$5, 2)<6), LEFT($H20, 1), "") | T20: =IF(AND(T$5>=$K20, T$5<=$L20, WEEKDAY(T$5, 2)<6), LEFT($H20, 1), "") | ... SC20: =IF(AND(SC$5>=$K20, SC$5<=$L20, WEEKDAY(SC$5, 2)<6), LEFT($H20, 1), "")
B21: 2809 | E21: 製作品納期 | H21: 製造管理 | I21: 完了 | J21: Production Control | K21: 45839 | L21: 45869 | M21: =IF(AND(M$5>=$K21, M$5<=$L21, WEEKDAY(M$5, 2)<6), LEFT($H21, 1), "") | N21: =IF(AND(N$5>=$K21, N$5<=$L21, WEEKDAY(N$5, 2)<6), LEFT($H21, 1), "") | O21: =IF(AND(O$5>=$K21, O$5<=$L21, WEEKDAY(O$5, 2)<6), LEFT($H21, 1), "") | P21: =IF(AND(P$5>=$K21, P$5<=$L21, WEEKDAY(P$5, 2)<6), LEFT($H21, 1), "") | Q21: =IF(AND(Q$5>=$K21, Q$5<=$L21, WEEKDAY(Q$5, 2)<6), LEFT($H21, 1), "") | R21: =IF(AND(R$5>=$K21, R$5<=$L21, WEEKDAY(R$5, 2)<6), LEFT($H21, 1), "") | S21: =IF(AND(S$5>=$K21, S$5<=$L21, WEEKDAY(S$5, 2)<6), LEFT($H21, 1), "") | T21: =IF(AND(T$5>=$K21, T$5<=$L21, WEEKDAY(T$5, 2)<6), LEFT($H21, 1), "") | ... SC21: =IF(AND(SC$5>=$K21, SC$5<=$L21, WEEKDAY(SC$5, 2)<6), LEFT($H21, 1), "")
B22: 2809 | E22: 組立図進捗 | H22: ー | I22: 完了 | J22: 出図状況 | K22: 45839 | L22: 45869 | M22: =IF(AND(M$5>=$K22, M$5<=$L22, WEEKDAY(M$5, 2)<6), LEFT($H22, 1), "") | N22: =IF(AND(N$5>=$K22, N$5<=$L22, WEEKDAY(N$5, 2)<6), LEFT($H22, 1), "") | O22: =IF(AND(O$5>=$K22, O$5<=$L22, WEEKDAY(O$5, 2)<6), LEFT($H22, 1), "") | P22: =IF(AND(P$5>=$K22, P$5<=$L22, WEEKDAY(P$5, 2)<6), LEFT($H22, 1), "") | Q22: =IF(AND(Q$5>=$K22, Q$5<=$L22, WEEKDAY(Q$5, 2)<6), LEFT($H22, 1), "") | R22: =IF(AND(R$5>=$K22, R$5<=$L22, WEEKDAY(R$5, 2)<6), LEFT($H22, 1), "") | S22: =IF(AND(S$5>=$K22, S$5<=$L22, WEEKDAY(S$5, 2)<6), LEFT($H22, 1), "") | T22: =IF(AND(T$5>=$K22, T$5<=$L22, WEEKDAY(T$5, 2)<6), LEFT($H22, 1), "") | ... SC22: =IF(AND(SC$5>=$K22, SC$5<=$L22, WEEKDAY(SC$5, 2)<6), LEFT($H22, 1), "")
B23: 2809 | E23: 神戸納入予定日 | H23: 製造管理 | I23: 完了 | J23: Production Control | K23: 45839 | L23: 45869 | M23: =IF(AND(M$5>=$K23, M$5<=$L23, WEEKDAY(M$5, 2)<6), LEFT($H23, 1), "") | N23: =IF(AND(N$5>=$K23, N$5<=$L23, WEEKDAY(N$5, 2)<6), LEFT($H23, 1), "") | O23: =IF(AND(O$5>=$K23, O$5<=$L23, WEEKDAY(O$5, 2)<6), LEFT($H23, 1), "") | P23: =IF(AND(P$5>=$K23, P$5<=$L23, WEEKDAY(P$5, 2)<6), LEFT($H23, 1), "") | Q23: =IF(AND(Q$5>=$K23, Q$5<=$L23, WEEKDAY(Q$5, 2)<6), LEFT($H23, 1), "") | R23: =IF(AND(R$5>=$K23, R$5<=$L23, WEEKDAY(R$5, 2)<6), LEFT($H23, 1), "") | S23: =IF(AND(S$5>=$K23, S$5<=$L23, WEEKDAY(S$5, 2)<6), LEFT($H23, 1), "") | T23: =IF(AND(T$5>=$K23, T$5<=$L23, WEEKDAY(T$5, 2)<6), LEFT($H23, 1), "") | ... SC23: =IF(AND(SC$5>=$K23, SC$5<=$L23, WEEKDAY(SC$5, 2)<6), LEFT($H23, 1), "")
B24: 2809 | E24: 艤装出図進捗 | H24: 電気技術 | I24: 完了 | J24: 出図状況 | K24: 45778 | L24: 45808 | M24: =IF(AND(M$5>=$K24, M$5<=$L24, WEEKDAY(M$5, 2)<6), LEFT($H24, 1), "") | N24: =IF(AND(N$5>=$K24, N$5<=$L24, WEEKDAY(N$5, 2)<6), LEFT($H24, 1), "") | O24: =IF(AND(O$5>=$K24, O$5<=$L24, WEEKDAY(O$5, 2)<6), LEFT($H24, 1), "") | P24: =IF(AND(P$5>=$K24, P$5<=$L24, WEEKDAY(P$5, 2)<6), LEFT($H24, 1), "") | Q24: =IF(AND(Q$5>=$K24, Q$5<=$L24, WEEKDAY(Q$5, 2)<6), LEFT($H24, 1), "") | R24: =IF(AND(R$5>=$K24, R$5<=$L24, WEEKDAY(R$5, 2)<6), LEFT($H24, 1), "") | S24: =IF(AND(S$5>=$K24, S$5<=$L24, WEEKDAY(S$5, 2)<6), LEFT($H24, 1), "") | T24: =IF(AND(T$5>=$K24, T$5<=$L24, WEEKDAY(T$5, 2)<6), LEFT($H24, 1), "") | ... SC24: =IF(AND(SC$5>=$K24, SC$5<=$L24, WEEKDAY(SC$5, 2)<6), LEFT($H24, 1), "")
B25: 2809 | E25: 製作品納期 | H25: 製造管理 | I25: 完了 | J25: Production Control | K25: 45717 | L25: 45874 | M25: =IF(AND(M$5>=$K25, M$5<=$L25, WEEKDAY(M$5, 2)<6), LEFT($H25, 1), "") | N25: =IF(AND(N$5>=$K25, N$5<=$L25, WEEKDAY(N$5, 2)<6), LEFT($H25, 1), "") | O25: =IF(AND(O$5>=$K25, O$5<=$L25, WEEKDAY(O$5, 2)<6), LEFT($H25, 1), "") | P25: =IF(AND(P$5>=$K25, P$5<=$L25, WEEKDAY(P$5, 2)<6), LEFT($H25, 1), "") | Q25: =IF(AND(Q$5>=$K25, Q$5<=$L25, WEEKDAY(Q$5, 2)<6), LEFT($H25, 1), "") | R25: =IF(AND(R$5>=$K25, R$5<=$L25, WEEKDAY(R$5, 2)<6), LEFT($H25, 1), "") | S25: =IF(AND(S$5>=$K25, S$5<=$L25, WEEKDAY(S$5, 2)<6), LEFT($H25, 1), "") | T25: =IF(AND(T$5>=$K25, T$5<=$L25, WEEKDAY(T$5, 2)<6), LEFT($H25, 1), "") | ... SC25: =IF(AND(SC$5>=$K25, SC$5<=$L25, WEEKDAY(SC$5, 2)<6), LEFT($H25, 1), "")
B26: 2809 | E26: 艤装組立図進捗 | H26: 電気技術 | I26: 完了 | J26: 出図状況 | K26: 45782 | L26: 45869 | M26: =IF(AND(M$5>=$K26, M$5<=$L26, WEEKDAY(M$5, 2)<6), LEFT($H26, 1), "") | N26: =IF(AND(N$5>=$K26, N$5<=$L26, WEEKDAY(N$5, 2)<6), LEFT($H26, 1), "") | O26: =IF(AND(O$5>=$K26, O$5<=$L26, WEEKDAY(O$5, 2)<6), LEFT($H26, 1), "") | P26: =IF(AND(P$5>=$K26, P$5<=$L26, WEEKDAY(P$5, 2)<6), LEFT($H26, 1), "") | Q26: =IF(AND(Q$5>=$K26, Q$5<=$L26, WEEKDAY(Q$5, 2)<6), LEFT($H26, 1), "") | R26: =IF(AND(R$5>=$K26, R$5<=$L26, WEEKDAY(R$5, 2)<6), LEFT($H26, 1), "") | S26: =IF(AND(S$5>=$K26, S$5<=$L26, WEEKDAY(S$5, 2)<6), LEFT($H26, 1), "") | T26: =IF(AND(T$5>=$K26, T$5<=$L26, WEEKDAY(T$5, 2)<6), LEFT($H26, 1), "") | ... SC26: =IF(AND(SC$5>=$K26, SC$5<=$L26, WEEKDAY(SC$5, 2)<6), LEFT($H26, 1), "")
B27: 2809 | E27: 神戸納入予定日 | H27: 製造管理 | I27: 完了 | J27: Production Control | K27: 45839 | L27: 45869 | M27: =IF(AND(M$5>=$K27, M$5<=$L27, WEEKDAY(M$5, 2)<6), LEFT($H27, 1), "") | N27: =IF(AND(N$5>=$K27, N$5<=$L27, WEEKDAY(N$5, 2)<6), LEFT($H27, 1), "") | O27: =IF(AND(O$5>=$K27, O$5<=$L27, WEEKDAY(O$5, 2)<6), LEFT($H27, 1), "") | P27: =IF(AND(P$5>=$K27, P$5<=$L27, WEEKDAY(P$5, 2)<6), LEFT($H27, 1), "") | Q27: =IF(AND(Q$5>=$K27, Q$5<=$L27, WEEKDAY(Q$5, 2)<6), LEFT($H27, 1), "") | R27: =IF(AND(R$5>=$K27, R$5<=$L27, WEEKDAY(R$5, 2)<6), LEFT($H27, 1), "") | S27: =IF(AND(S$5>=$K27, S$5<=$L27, WEEKDAY(S$5, 2)<6), LEFT($H27, 1), "") | T27: =IF(AND(T$5>=$K27, T$5<=$L27, WEEKDAY(T$5, 2)<6), LEFT($H27, 1), "") | ... SC27: =IF(AND(SC$5>=$K27, SC$5<=$L27, WEEKDAY(SC$5, 2)<6), LEFT($H27, 1), "")
B28: 2809 | E28: 最終電気図面 | H28: 電気技術 | I28: 完了 | J28: 電気工程会議 | K28: 45809 | L28: 45818 | M28: =IF(AND(M$5>=$K28, M$5<=$L28, WEEKDAY(M$5, 2)<6), LEFT($H28, 1), "") | N28: =IF(AND(N$5>=$K28, N$5<=$L28, WEEKDAY(N$5, 2)<6), LEFT($H28, 1), "") | O28: =IF(AND(O$5>=$K28, O$5<=$L28, WEEKDAY(O$5, 2)<6), LEFT($H28, 1), "") | P28: =IF(AND(P$5>=$K28, P$5<=$L28, WEEKDAY(P$5, 2)<6), LEFT($H28, 1), "") | Q28: =IF(AND(Q$5>=$K28, Q$5<=$L28, WEEKDAY(Q$5, 2)<6), LEFT($H28, 1), "") | R28: =IF(AND(R$5>=$K28, R$5<=$L28, WEEKDAY(R$5, 2)<6), LEFT($H28, 1), "") | S28: =IF(AND(S$5>=$K28, S$5<=$L28, WEEKDAY(S$5, 2)<6), LEFT($H28, 1), "") | T28: =IF(AND(T$5>=$K28, T$5<=$L28, WEEKDAY(T$5, 2)<6), LEFT($H28, 1), "") | ... SC28: =IF(AND(SC$5>=$K28, SC$5<=$L28, WEEKDAY(SC$5, 2)<6), LEFT($H28, 1), "")
B29: 2809 | D29: 組立 | E29: 盤組立 | H29: 守時 | I29: 完了 | J29: 組立工程表 | K29: 45873 | L29: 45891 | M29: =IF(AND(M$5>=$K29, M$5<=$L29, WEEKDAY(M$5, 2)<6), LEFT($H29, 1), "") | N29: =IF(AND(N$5>=$K29, N$5<=$L29, WEEKDAY(N$5, 2)<6), LEFT($H29, 1), "") | O29: =IF(AND(O$5>=$K29, O$5<=$L29, WEEKDAY(O$5, 2)<6), LEFT($H29, 1), "") | P29: =IF(AND(P$5>=$K29, P$5<=$L29, WEEKDAY(P$5, 2)<6), LEFT($H29, 1), "") | Q29: =IF(AND(Q$5>=$K29, Q$5<=$L29, WEEKDAY(Q$5, 2)<6), LEFT($H29, 1), "") | R29: =IF(AND(R$5>=$K29, R$5<=$L29, WEEKDAY(R$5, 2)<6), LEFT($H29, 1), "") | S29: =IF(AND(S$5>=$K29, S$5<=$L29, WEEKDAY(S$5, 2)<6), LEFT($H29, 1), "") | T29: =IF(AND(T$5>=$K29, T$5<=$L29, WEEKDAY(T$5, 2)<6), LEFT($H29, 1), "") | ... SC29: =IF(AND(SC$5>=$K29, SC$5<=$L29, WEEKDAY(SC$5, 2)<6), LEFT($H29, 1), "")
B30: 2809 | H30: 守時 | I30: 完了 | K30: 45887 | L30: 45898 | M30: =IF(AND(M$5>=$K30, M$5<=$L30, WEEKDAY(M$5, 2)<6), LEFT($H30, 1), "") | N30: =IF(AND(N$5>=$K30, N$5<=$L30, WEEKDAY(N$5, 2)<6), LEFT($H30, 1), "") | O30: =IF(AND(O$5>=$K30, O$5<=$L30, WEEKDAY(O$5, 2)<6), LEFT($H30, 1), "") | P30: =IF(AND(P$5>=$K30, P$5<=$L30, WEEKDAY(P$5, 2)<6), LEFT($H30, 1), "") | Q30: =IF(AND(Q$5>=$K30, Q$5<=$L30, WEEKDAY(Q$5, 2)<6), LEFT($H30, 1), "") | R30: =IF(AND(R$5>=$K30, R$5<=$L30, WEEKDAY(R$5, 2)<6), LEFT($H30, 1), "") | S30: =IF(AND(S$5>=$K30, S$5<=$L30, WEEKDAY(S$5, 2)<6), LEFT($H30, 1), "") | T30: =IF(AND(T$5>=$K30, T$5<=$L30, WEEKDAY(T$5, 2)<6), LEFT($H30, 1), "") | ... SC30: =IF(AND(SC$5>=$K30, SC$5<=$L30, WEEKDAY(SC$5, 2)<6), LEFT($H30, 1), "")
B31: 2809 | E31: 塗装 | I31: 完了 | M31: =IF(AND(M$5>=$K31, M$5<=$L31, WEEKDAY(M$5, 2)<6), LEFT($H31, 1), "") | N31: =IF(AND(N$5>=$K31, N$5<=$L31, WEEKDAY(N$5, 2)<6), LEFT($H31, 1), "") | O31: =IF(AND(O$5>=$K31, O$5<=$L31, WEEKDAY(O$5, 2)<6), LEFT($H31, 1), "") | P31: =IF(AND(P$5>=$K31, P$5<=$L31, WEEKDAY(P$5, 2)<6), LEFT($H31, 1), "") | Q31: =IF(AND(Q$5>=$K31, Q$5<=$L31, WEEKDAY(Q$5, 2)<6), LEFT($H31, 1), "") | R31: =IF(AND(R$5>=$K31, R$5<=$L31, WEEKDAY(R$5, 2)<6), LEFT($H31, 1), "") | S31: =IF(AND(S$5>=$K31, S$5<=$L31, WEEKDAY(S$5, 2)<6), LEFT($H31, 1), "") | T31: =IF(AND(T$5>=$K31, T$5<=$L31, WEEKDAY(T$5, 2)<6), LEFT($H31, 1), "") | ... SC31: =IF(AND(SC$5>=$K31, SC$5<=$L31, WEEKDAY(SC$5, 2)<6), LEFT($H31, 1), "")
B32: 2809 | E32: 据付 | I32: 完了 | M32: =IF(AND(M$5>=$K32, M$5<=$L32, WEEKDAY(M$5, 2)<6), LEFT($H32, 1), "") | N32: =IF(AND(N$5>=$K32, N$5<=$L32, WEEKDAY(N$5, 2)<6), LEFT($H32, 1), "") | O32: =IF(AND(O$5>=$K32, O$5<=$L32, WEEKDAY(O$5, 2)<6), LEFT($H32, 1), "") | P32: =IF(AND(P$5>=$K32, P$5<=$L32, WEEKDAY(P$5, 2)<6), LEFT($H32, 1), "") | Q32: =IF(AND(Q$5>=$K32, Q$5<=$L32, WEEKDAY(Q$5, 2)<6), LEFT($H32, 1), "") | R32: =IF(AND(R$5>=$K32, R$5<=$L32, WEEKDAY(R$5, 2)<6), LEFT($H32, 1), "") | S32: =IF(AND(S$5>=$K32, S$5<=$L32, WEEKDAY(S$5, 2)<6), LEFT($H32, 1), "") | T32: =IF(AND(T$5>=$K32, T$5<=$L32, WEEKDAY(T$5, 2)<6), LEFT($H32, 1), "") | ... SC32: =IF(AND(SC$5>=$K32, SC$5<=$L32, WEEKDAY(SC$5, 2)<6), LEFT($H32, 1), "")
B33: 2809 | E33: 組立 | F33: FL | G33: GS | H33: 米澤 | I33: 完了 | K33: {=_xlfn.XLOOKUP($C$8&F33,テーブル1!$A:$A&テーブル1!$B:$B,テーブル1!$C:$C, "")} -> 45887 | L33: {=_xlfn.XLOOKUP($C$8&F33,テーブル1!$A:$A&テーブル1!$B:$B,テーブル1!$D:$D, "")} -> 46003 | M33: =IF(AND(M$5>=$K33, M$5<=$L33, WEEKDAY(M$5, 2)<6), LEFT($H33, 1), "") | N33: =IF(AND(N$5>=$K33, N$5<=$L33, WEEKDAY(N$5, 2)<6), LEFT($H33, 1), "") | O33: =IF(AND(O$5>=$K33, O$5<=$L33, WEEKDAY(O$5, 2)<6), LEFT($H33, 1), "") | P33: =IF(AND(P$5>=$K33, P$5<=$L33, WEEKDAY(P$5, 2)<6), LEFT($H33, 1), "") | Q33: =IF(AND(Q$5>=$K33, Q$5<=$L33, WEEKDAY(Q$5, 2)<6), LEFT($H33, 1), "") | R33: =IF(AND(R$5>=$K33, R$5<=$L33, WEEKDAY(R$5, 2)<6), LEFT($H33, 1), "") | S33: =IF(AND(S$5>=$K33, S$5<=$L33, WEEKDAY(S$5, 2)<6), LEFT($H33, 1), "") | T33: =IF(AND(T$5>=$K33, T$5<=$L33, WEEKDAY(T$5, 2)<6), LEFT($H33, 1), "") | ... SC33: =IF(AND(SC$5>=$K33, SC$5<=$L33, WEEKDAY(SC$5, 2)<6), LEFT($H33, 1), "")
B34: 2809 | F34: SW | G34: ー | H34: 古賀 | I34: 完了 | K34: {=_xlfn.XLOOKUP($C$8&F34,テーブル1!$A:$A&テーブル1!$B:$B,テーブル1!$C:$C, "")} -> 45887 | L34: {=_xlfn.XLOOKUP($C$8&F34,テーブル1!$A:$A&テーブル1!$B:$B,テーブル1!$D:$D, "")} -> 46003 | M34: =IF(AND(M$5>=$K34, M$5<=$L34, WEEKDAY(M$5, 2)<6), LEFT($H34, 1), "") | N34: =IF(AND(N$5>=$K34, N$5<=$L34, WEEKDAY(N$5, 2)<6), LEFT($H34, 1), "") | O34: =IF(AND(O$5>=$K34, O$5<=$L34, WEEKDAY(O$5, 2)<6), LEFT($H34, 1), "") | P34: =IF(AND(P$5>=$K34, P$5<=$L34, WEEKDAY(P$5, 2)<6), LEFT($H34, 1), "") | Q34: =IF(AND(Q$5>=$K34, Q$5<=$L34, WEEKDAY(Q$5, 2)<6), LEFT($H34, 1), "") | R34: =IF(AND(R$5>=$K34, R$5<=$L34, WEEKDAY(R$5, 2)<6), LEFT($H34, 1), "") | S34: =IF(AND(S$5>=$K34, S$5<=$L34, WEEKDAY(S$5, 2)<6), LEFT($H34, 1), "") | T34: =IF(AND(T$5>=$K34, T$5<=$L34, WEEKDAY(T$5, 2)<6), LEFT($H34, 1), "") | ... SC34: =IF(AND(SC$5>=$K34, SC$5<=$L34, WEEKDAY(SC$5, 2)<6), LEFT($H34, 1), "")
B35: 2809 | F35: UC | G35: ー | H35: 桂/長谷川 | I35: 完了 | K35: {=_xlfn.XLOOKUP($C$8&F35,テーブル1!$A:$A&テーブル1!$B:$B,テーブル1!$C:$C, "")} -> 45887 | L35: {=_xlfn.XLOOKUP($C$8&F35,テーブル1!$A:$A&テーブル1!$B:$B,テーブル1!$D:$D, "")} -> 46017 | M35: =IF(AND(M$5>=$K35, M$5<=$L35, WEEKDAY(M$5, 2)<6), LEFT($H35, 1), "") | N35: =IF(AND(N$5>=$K35, N$5<=$L35, WEEKDAY(N$5, 2)<6), LEFT($H35, 1), "") | O35: =IF(AND(O$5>=$K35, O$5<=$L35, WEEKDAY(O$5, 2)<6), LEFT($H35, 1), "") | P35: =IF(AND(P$5>=$K35, P$5<=$L35, WEEKDAY(P$5, 2)<6), LEFT($H35, 1), "") | Q35: =IF(AND(Q$5>=$K35, Q$5<=$L35, WEEKDAY(Q$5, 2)<6), LEFT($H35, 1), "") | R35: =IF(AND(R$5>=$K35, R$5<=$L35, WEEKDAY(R$5, 2)<6), LEFT($H35, 1), "") | S35: =IF(AND(S$5>=$K35, S$5<=$L35, WEEKDAY(S$5, 2)<6), LEFT($H35, 1), "") | T35: =IF(AND(T$5>=$K35, T$5<=$L35, WEEKDAY(T$5, 2)<6), LEFT($H35, 1), "") | ... SC35: =IF(AND(SC$5>=$K35, SC$5<=$L35, WEEKDAY(SC$5, 2)<6), LEFT($H35, 1), "")
B36: 2809 | F36: LM | G36: ー | H36: 香西 | I36: 完了 | K36: {=_xlfn.XLOOKUP($C$8&F36,テーブル1!$A:$A&テーブル1!$B:$B,テーブル1!$C:$C, "")} -> 45866 | L36: {=_xlfn.XLOOKUP($C$8&F36,テーブル1!$A:$A&テーブル1!$B:$B,テーブル1!$D:$D, "")} -> 45891 | M36: =IF(AND(M$5>=$K36, M$5<=$L36, WEEKDAY(M$5, 2)<6), LEFT($H36, 1), "") | N36: =IF(AND(N$5>=$K36, N$5<=$L36, WEEKDAY(N$5, 2)<6), LEFT($H36, 1), "") | O36: =IF(AND(O$5>=$K36, O$5<=$L36, WEEKDAY(O$5, 2)<6), LEFT($H36, 1), "") | P36: =IF(AND(P$5>=$K36, P$5<=$L36, WEEKDAY(P$5, 2)<6), LEFT($H36, 1), "") | Q36: =IF(AND(Q$5>=$K36, Q$5<=$L36, WEEKDAY(Q$5, 2)<6), LEFT($H36, 1), "") | R36: =IF(AND(R$5>=$K36, R$5<=$L36, WEEKDAY(R$5, 2)<6), LEFT($H36, 1), "") | S36: =IF(AND(S$5>=$K36, S$5<=$L36, WEEKDAY(S$5, 2)<6), LEFT($H36, 1), "") | T36: =IF(AND(T$5>=$K36, T$5<=$L36, WEEKDAY(T$5, 2)<6), LEFT($H36, 1), "") | ... SC36: =IF(AND(SC$5>=$K36, SC$5<=$L36, WEEKDAY(SC$5, 2)<6), LEFT($H36, 1), "")
B37: 2809 | F37: LE | G37: ー | H37: 山下 | I37: 完了 | K37: {=_xlfn.XLOOKUP($C$8&F37,テーブル1!$A:$A&テーブル1!$B:$B,テーブル1!$C:$C, "")} -> 45901 | L37: {=_xlfn.XLOOKUP($C$8&F37,テーブル1!$A:$A&テーブル1!$B:$B,テーブル1!$D:$D, "")} -> 45940 | M37: =IF(AND(M$5>=$K37, M$5<=$L37, WEEKDAY(M$5, 2)<6), LEFT($H37, 1), "") | N37: =IF(AND(N$5>=$K37, N$5<=$L37, WEEKDAY(N$5, 2)<6), LEFT($H37, 1), "") | O37: =IF(AND(O$5>=$K37, O$5<=$L37, WEEKDAY(O$5, 2)<6), LEFT($H37, 1), "") | P37: =IF(AND(P$5>=$K37, P$5<=$L37, WEEKDAY(P$5, 2)<6), LEFT($H37, 1), "") | Q37: =IF(AND(Q$5>=$K37, Q$5<=$L37, WEEKDAY(Q$5, 2)<6), LEFT($H37, 1), "") | R37: =IF(AND(R$5>=$K37, R$5<=$L37, WEEKDAY(R$5, 2)<6), LEFT($H37, 1), "") | S37: =IF(AND(S$5>=$K37, S$5<=$L37, WEEKDAY(S$5, 2)<6), LEFT($H37, 1), "") | T37: =IF(AND(T$5>=$K37, T$5<=$L37, WEEKDAY(T$5, 2)<6), LEFT($H37, 1), "") | ... SC37: =IF(AND(SC$5>=$K37, SC$5<=$L37, WEEKDAY(SC$5, 2)<6), LEFT($H37, 1), "")
B38: 2809 | E38: 電気艤装 | F38: FL | G38: ー | H38: 木村(至) | I38: 完了 | K38: {=_xlfn.XLOOKUP($C$8&F38,テーブル1!$A:$A&テーブル1!$B:$B,テーブル1!$E:$E, "")} -> 45985 | L38: {=_xlfn.XLOOKUP($C$8&F38,テーブル1!$A:$A&テーブル1!$B:$B,テーブル1!$F:$F, "")} -> 46003 | M38: =IF(AND(M$5>=$K38, M$5<=$L38, WEEKDAY(M$5, 2)<6), LEFT($H38, 1), "") | N38: =IF(AND(N$5>=$K38, N$5<=$L38, WEEKDAY(N$5, 2)<6), LEFT($H38, 1), "") | O38: =IF(AND(O$5>=$K38, O$5<=$L38, WEEKDAY(O$5, 2)<6), LEFT($H38, 1), "") | P38: =IF(AND(P$5>=$K38, P$5<=$L38, WEEKDAY(P$5, 2)<6), LEFT($H38, 1), "") | Q38: =IF(AND(Q$5>=$K38, Q$5<=$L38, WEEKDAY(Q$5, 2)<6), LEFT($H38, 1), "") | R38: =IF(AND(R$5>=$K38, R$5<=$L38, WEEKDAY(R$5, 2)<6), LEFT($H38, 1), "") | S38: =IF(AND(S$5>=$K38, S$5<=$L38, WEEKDAY(S$5, 2)<6), LEFT($H38, 1), "") | T38: =IF(AND(T$5>=$K38, T$5<=$L38, WEEKDAY(T$5, 2)<6), LEFT($H38, 1), "") | ... SC38: =IF(AND(SC$5>=$K38, SC$5<=$L38, WEEKDAY(SC$5, 2)<6), LEFT($H38, 1), "")
B39: 2809 | F39: SW | G39: ー | H39: 木村(至) | I39: 完了 | K39: {=_xlfn.XLOOKUP($C$8&F39,テーブル1!$A:$A&テーブル1!$B:$B,テーブル1!$E:$E, "")} -> 45992 | L39: {=_xlfn.XLOOKUP($C$8&F39,テーブル1!$A:$A&テーブル1!$B:$B,テーブル1!$F:$F, "")} -> 46010 | M39: =IF(AND(M$5>=$K39, M$5<=$L39, WEEKDAY(M$5, 2)<6), LEFT($H39, 1), "") | N39: =IF(AND(N$5>=$K39, N$5<=$L39, WEEKDAY(N$5, 2)<6), LEFT($H39, 1), "") | O39: =IF(AND(O$5>=$K39, O$5<=$L39, WEEKDAY(O$5, 2)<6), LEFT($H39, 1), "") | P39: =IF(AND(P$5>=$K39, P$5<=$L39, WEEKDAY(P$5, 2)<6), LEFT($H39, 1), "") | Q39: =IF(AND(Q$5>=$K39, Q$5<=$L39, WEEKDAY(Q$5, 2)<6), LEFT($H39, 1), "") | R39: =IF(AND(R$5>=$K39, R$5<=$L39, WEEKDAY(R$5, 2)<6), LEFT($H39, 1), "") | S39: =IF(AND(S$5>=$K39, S$5<=$L39, WEEKDAY(S$5, 2)<6), LEFT($H39, 1), "") | T39: =IF(AND(T$5>=$K39, T$5<=$L39, WEEKDAY(T$5, 2)<6), LEFT($H39, 1), "") | ... SC39: =IF(AND(SC$5>=$K39, SC$5<=$L39, WEEKDAY(SC$5, 2)<6), LEFT($H39, 1), "")
B40: 2809 | F40: UC | G40: ー | H40: 木村(至) | I40: 完了 | K40: {=_xlfn.XLOOKUP($C$8&F40,テーブル1!$A:$A&テーブル1!$B:$B,テーブル1!$E:$E, "")} -> 45992 | L40: {=_xlfn.XLOOKUP($C$8&F40,テーブル1!$A:$A&テーブル1!$B:$B,テーブル1!$F:$F, "")} -> 46017 | M40: =IF(AND(M$5>=$K40, M$5<=$L40, WEEKDAY(M$5, 2)<6), LEFT($H40, 1), "") | N40: =IF(AND(N$5>=$K40, N$5<=$L40, WEEKDAY(N$5, 2)<6), LEFT($H40, 1), "") | O40: =IF(AND(O$5>=$K40, O$5<=$L40, WEEKDAY(O$5, 2)<6), LEFT($H40, 1), "") | P40: =IF(AND(P$5>=$K40, P$5<=$L40, WEEKDAY(P$5, 2)<6), LEFT($H40, 1), "") | Q40: =IF(AND(Q$5>=$K40, Q$5<=$L40, WEEKDAY(Q$5, 2)<6), LEFT($H40, 1), "") | R40: =IF(AND(R$5>=$K40, R$5<=$L40, WEEKDAY(R$5, 2)<6), LEFT($H40, 1), "") | S40: =IF(AND(S$5>=$K40, S$5<=$L40, WEEKDAY(S$5, 2)<6), LEFT($H40, 1), "") | T40: =IF(AND(T$5>=$K40, T$5<=$L40, WEEKDAY(T$5, 2)<6), LEFT($H40, 1), "") | ... SC40: =IF(AND(SC$5>=$K40, SC$5<=$L40, WEEKDAY(SC$5, 2)<6), LEFT($H40, 1), "")
